Workbook

Sheet Child SKUs - Alias Master
A1: Seller SKU | B1: Chck | C1: O.SR | D1: MTP SKU | E1: MTP Name | F1: Child Color | G1: SKU Product Name | H1: MRP | I1: Barcode | J1: FNSKU | K1: ASIN | L1: FK FSN | M1: FK List.ID | N1: UL | O1: PF | P1: PF WH SKU | Q1: Myntra
A2: SR-CLM-TM | B2: =IFERROR(VLOOKUP(Table1[[#This Row],[Seller SKU]],'[1]FG Snapshot (V2)'!$A:$B,2,0),"AR") -> Y | C2: =IFERROR(VLOOKUP(Table1[[#This Row],[Seller SKU]],'[1]FG Snapshot (V2)'!$A:$E,5,0),"AR") -> 1 | D2: SR-CLM-T | E2: =VLOOKUP(Table1[[#This Row],[MTP SKU]],'MTP SKUs - Master Data'!A:D,3,0) -> Carlem Tall Design Shoe Rack | F2: Brown Maple | G2: =_xlfn.CONCAT(Table1[[#This Row],[MTP Name]]," ",Table1[[#This Row],[ Child Color]]) -> Carlem Tall Design Shoe Rack Brown Maple | H2: =VLOOKUP(Table1[[#This Row],[MTP SKU]],'MTP SKUs - Master Data'!A:D,3,0) -> Carlem Tall Design Shoe Rack | J2: #N/A | K2: B0DG9834LM | L2: SHKH4FQ2G6XVBAWG | M2: LSTSHKH4FQ2G6XVBAWGDAI5VU | N2: FVSGSR11BM51569 | O2: FN2200964-S-PM39235 | P2: FN2200964-S-WH41218 | Q2: 34399022
A3: TU-WBM-MF | B3: =IFERROR(VLOOKUP(Table1[[#This Row],[Seller SKU]],'[1]FG Snapshot (V2)'!$A:$B,2,0),"AR") -> Y | C3: =IFERROR(VLOOKUP(Table1[[#This Row],[Seller SKU]],'[1]FG Snapshot (V2)'!$A:$E,5,0),"AR") -> 5 | D3: TU-WBM | E3: =VLOOKUP(Table1[[#This Row],[MTP SKU]],'MTP SKUs - Master Data'!A:D,3,0) -> Wilbrome TV Unit | F3: Brown Maple & White | G3: =_xlfn.CONCAT(Table1[[#This Row],[MTP Name]]," ",Table1[[#This Row],[ Child Color]]) -> Wilbrome TV Unit Brown Maple & White | H3: =VLOOKUP(Table1[[#This Row],[MTP SKU]],'MTP SKUs - Master Data'!A:D,3,0) -> Wilbrome TV Unit | J3: X0023REYJ9 | K3: B0CJC6PTKS | L3: TVUGUGZ55QPQGEHY | M3: LSTTVUGUGZ55QPQGEHY8HJVMU | N3: FVTBAV33BR32705 | O3: FN2135043-S-PM39235 | P3: FN2135043-S-WH41218 | Q3: 34399074
A4: TU-BKY-M | B4: =IFERROR(VLOOKUP(Table1[[#This Row],[Seller SKU]],'[1]FG Snapshot (V2)'!$A:$B,2,0),"AR") -> Y | C4: =IFERROR(VLOOKUP(Table1[[#This Row],[Seller SKU]],'[1]FG Snapshot (V2)'!$A:$E,5,0),"AR") -> 2 | D4: TU-BKY | E4: =VLOOKUP(Table1[[#This Row],[MTP SKU]],'MTP SKUs - Master Data'!A:D,3,0) -> Blesky TV Unit | F4: Brown Maple | G4: =_xlfn.CONCAT(Table1[[#This Row],[MTP Name]]," ",Table1[[#This Row],[ Child Color]]) -> Blesky TV Unit Brown Maple | H4: =VLOOKUP(Table1[[#This Row],[MTP SKU]],'MTP SKUs - Master Data'!A:D,3,0) -> Blesky TV Unit | J4: #N/A | K4: B0DFPSHRLG | L4: TVUH48ZZFZFFTYZH | M4: LSTTVUH48ZZFZFFTYZHBYMZVY | N4: FVSGAV11BM51538 | O4: FN2200968-S-PM39235 | P4: FN2200968-S-WH41218 | Q4: 34399027
A5: TU-SKD-WF | B5: =IFERROR(VLOOKUP(Table1[[#This Row],[Seller SKU]],'[1]FG Snapshot (V2)'!$A:$B,2,0),"AR") -> Y | C5: =IFERROR(VLOOKUP(Table1[[#This Row],[Seller SKU]],'[1]FG Snapshot (V2)'!$A:$E,5,0),"AR") -> 8 | D5: TU-SKD | E5: =VLOOKUP(Table1[[#This Row],[MTP SKU]],'MTP SKUs - Master Data'!A:D,3,0) -> Skiddo TV Unit | F5: Wenge & White | G5: =_xlfn.CONCAT(Table1[[#This Row],[MTP Name]]," ",Table1[[#This Row],[ Child Color]]) -> Skiddo TV Unit Wenge & White | H5: =VLOOKUP(Table1[[#This Row],[MTP SKU]],'MTP SKUs - Master Data'!A:D,3,0) -> Skiddo TV Unit | J5: X0023REYIZ | K5: B0BCZ4GVFM | L5: TVUGG2FKZKVE897E | M5: LSTTVUGG2FKZKVE897E7WSGLU | N5: FVTBAV33BR70800 | O5: FN2087160-S-PM39235 | P5: FN2087160-S-WH41218 | Q5: #N/A
A6: PU-SNM-F | B6: =IFERROR(VLOOKUP(Table1[[#This Row],[Seller SKU]],'[1]FG Snapshot (V2)'!$A:$B,2,0),"AR") -> NL | C6: =IFERROR(VLOOKUP(Table1[[#This Row],[Seller SKU]],'[1]FG Snapshot (V2)'!$A:$E,5,0),"AR") -> 4 | D6: PU-SNM | E6: =VLOOKUP(Table1[[#This Row],[MTP SKU]],'MTP SKUs - Master Data'!A:D,3,0) -> Sharnam Pooja Unit | F6: White | G6: =_xlfn.CONCAT(Table1[[#This Row],[MTP Name]]," ",Table1[[#This Row],[ Child Color]]) -> Sharnam Pooja Unit White | H6: =VLOOKUP(Table1[[#This Row],[MTP SKU]],'MTP SKUs - Master Data'!A:D,3,0) -> Sharnam Pooja Unit | K6: B0FGVBK5KB | L6: HTEHDWFAK35EYHA3 | M6: LSTHTEHDWFAK35EYHA3P0TGWN | N6: FVSGPR11WH51575 | O6: KD2280098-S-PM39397 | P6: Not in WH | Q6: #N/A
A7: TU-SKD-MF | B7: =IFERROR(VLOOKUP(Table1[[#This Row],[Seller SKU]],'[1]FG Snapshot (V2)'!$A:$B,2,0),"AR") -> Y | C7: =IFERROR(VLOOKUP(Table1[[#This Row],[Seller SKU]],'[1]FG Snapshot (V2)'!$A:$E,5,0),"AR") -> 7 | D7: TU-SKD | E7: =VLOOKUP(Table1[[#This Row],[MTP SKU]],'MTP SKUs - Master Data'!A:D,3,0) -> Skiddo TV Unit | F7: Brown Maple & White | G7: =_xlfn.CONCAT(Table1[[#This Row],[MTP Name]]," ",Table1[[#This Row],[ Child Color]]) -> Skiddo TV Unit Brown Maple & White | H7: =VLOOKUP(Table1[[#This Row],[MTP SKU]],'MTP SKUs - Master Data'!A:D,3,0) -> Skiddo TV Unit | J7: X0023RTQJH | K7: B0CJLRT2TR | L7: TVUGUGZAHZGDRSFH | M7: LSTTVUGUGZAHZGDRSFH1SZQVK | N7: FVTBAV33BR32706 | O7: FN2152519-S-PM39235 | P7: FN2152519-S-WH41218 | Q7: 34398993
A8: W-MLT-4NMF | B8: =IFERROR(VLOOKUP(Table1[[#This Row],[Seller SKU]],'[1]FG Snapshot (V2)'!$A:$B,2,0),"AR") -> RL | C8: =IFERROR(VLOOKUP(Table1[[#This Row],[Seller SKU]],'[1]FG Snapshot (V2)'!$A:$E,5,0),"AR") -> 14 | D8: W-MLT-4N | E8: =VLOOKUP(Table1[[#This Row],[MTP SKU]],'MTP SKUs - Master Data'!A:D,3,0) -> Maltein 4 Door Without Mirror Wardrobe | F8: Brown Maple & White | G8: =_xlfn.CONCAT(Table1[[#This Row],[MTP Name]]," ",Table1[[#This Row],[ Child Color]]) -> Maltein 4 Door Without Mirror Wardrobe Brown Maple & White | H8: =VLOOKUP(Table1[[#This Row],[MTP SKU]],'MTP SKUs - Master Data'!A:D,3,0) -> Maltein 4 Door Without Mirror Wardrobe | K8: B0FDVHM7XN | L8: WCLHDTDAXGCVRGGD | M8: LSTWCLHDTDAXGCVRGGDNCGVVY | N8: FVSGCB11BW51520 | O8: FN2260676-S-PM39235 | P8: FN2260676-S-WH41218 | Q8: #N/A
A9: ST-CBN-LSMF | B9: =IFERROR(VLOOKUP(Table1[[#This Row],[Seller SKU]],'[1]FG Snapshot (V2)'!$A:$B,2,0),"AR") -> Y | C9: =IFERROR(VLOOKUP(Table1[[#This Row],[Seller SKU]],'[1]FG Snapshot (V2)'!$A:$E,5,0),"AR") -> 25 | D9: ST-CBN-LS | E9: =VLOOKUP(Table1[[#This Row],[MTP SKU]],'MTP SKUs - Master Data'!A:D,3,0) -> Corbyn L-Shape Study Table | F9: Brown Maple & White | G9: =_xlfn.CONCAT(Table1[[#This Row],[MTP Name]]," ",Table1[[#This Row],[ Child Color]]) -> Corbyn L-Shape Study Table Brown Maple & White | H9: =VLOOKUP(Table1[[#This Row],[MTP SKU]],'MTP SKUs - Master Data'!A:D,3,0) -> Corbyn L-Shape Study Table | J9: #N/A | K9: B0DFQ1Q1LJ | L9: OSTHAYGSVZ5TZJRE | M9: LSTOSTHAYGSVZ5TZJRE1LYIVS | N9: FVTBST11BW51562 | O9: FN2200965-S-PM39235 | P9: FN2200965-S-WH41218 | Q9: 34399075
A10: W-MLT-3NMF | B10: =IFERROR(VLOOKUP(Table1[[#This Row],[Seller SKU]],'[1]FG Snapshot (V2)'!$A:$B,2,0),"AR") -> Y | C10: =IFERROR(VLOOKUP(Table1[[#This Row],[Seller SKU]],'[1]FG Snapshot (V2)'!$A:$E,5,0),"AR") -> 21 | D10: W-MLT-3N | E10: =VLOOKUP(Table1[[#This Row],[MTP SKU]],'MTP SKUs - Master Data'!A:D,3,0) -> Maltein 3 Door Without Mirror Wardrobe | F10: Brown Maple & White | G10: =_xlfn.CONCAT(Table1[[#This Row],[MTP Name]]," ",Table1[[#This Row],[ Child Color]]) -> Maltein 3 Door Without Mirror Wardrobe Brown Maple & White | H10: =VLOOKUP(Table1[[#This Row],[MTP SKU]],'MTP SKUs - Master Data'!A:D,3,0) -> Maltein 3 Door Without Mirror Wardrobe | K10: B0FDW1B81W | L10: WCLHDUERQCB3KWG3 | M10: LSTWCLHDUERQCB3KWG3Z9CHDZ | N10: FVSGCB11BW51519 | O10: FN2260675-S-PM39235 | P10: FN2260675-S-WH41218 | Q10: #N/A
A11: CT-SH.E-MI | B11: =IFERROR(VLOOKUP(Table1[[#This Row],[Seller SKU]],'[1]FG Snapshot (V2)'!$A:$B,2,0),"AR") -> Y | C11: =IFERROR(VLOOKUP(Table1[[#This Row],[Seller SKU]],'[1]FG Snapshot (V2)'!$A:$E,5,0),"AR") -> 13 | D11: CT-SH | E11: =VLOOKUP(Table1[[#This Row],[MTP SKU]],'MTP SKUs - Master Data'!A:D,3,0) -> Smohn Coffee Table | F11: Brown Maple & Beige | G11: =_xlfn.CONCAT(Table1[[#This Row],[MTP Name]]," ",Table1[[#This Row],[ Child Color]]) -> Smohn Coffee Table Brown Maple & Beige | H11: =VLOOKUP(Table1[[#This Row],[MTP SKU]],'MTP SKUs - Master Data'!A:D,3,0) -> Smohn Coffee Table | J11: X001VCIAFL | K11: B0C8J81BP6 | L11: CFTH2QF2E6NJTFGD | M11: LSTCFTH2QF2E6NJTFGDTEKR8H | N11: FVTBCF33BR50150 | O11: FN2194296-S-PM39235 | P11: Not in WH | Q11: 34399060
A12: ST-AML-MI | B12: =IFERROR(VLOOKUP(Table1[[#This Row],[Seller SKU]],'[1]FG Snapshot (V2)'!$A:$B,2,0),"AR") -> Y | C12: =IFERROR(VLOOKUP(Table1[[#This Row],[Seller SKU]],'[1]FG Snapshot (V2)'!$A:$E,5,0),"AR") -> 19 | D12: ST-AML | E12: =VLOOKUP(Table1[[#This Row],[MTP SKU]],'MTP SKUs - Master Data'!A:D,3,0) -> Amalet Study Table | F12: Brown Maple & Beige | G12: =_xlfn.CONCAT(Table1[[#This Row],[MTP Name]]," ",Table1[[#This Row],[ Child Color]]) -> Amalet Study Table Brown Maple & Beige | H12: =VLOOKUP(Table1[[#This Row],[MTP SKU]],'MTP SKUs - Master Data'!A:D,3,0) -> Amalet Study Table | J12: X0024E1F2P | K12: B07N3WXJJ5 | L12: OSTGUJYGB83ZH9PB | M12: LSTOSTGUJYGB83ZH9PBF06U6Y | N12: FVTBST33BR72381 | O12: FN2152512-S-PM39235 | P12: FN2152512-S-WH41218 | Q12: 34399107
A13: W-CLO-5M | B13: =IFERROR(VLOOKUP(Table1[[#This Row],[Seller SKU]],'[1]FG Snapshot (V2)'!$A:$B,2,0),"AR") -> Y | C13: =IFERROR(VLOOKUP(Table1[[#This Row],[Seller SKU]],'[1]FG Snapshot (V2)'!$A:$E,5,0),"AR") -> 16 | D13: W-CLO-5 | E13: =VLOOKUP(Table1[[#This Row],[MTP SKU]],'MTP SKUs - Master Data'!A:D,3,0) -> Calcio 5-Tier Wardrobe | F13: Brown Maple | G13: =_xlfn.CONCAT(Table1[[#This Row],[MTP Name]]," ",Table1[[#This Row],[ Child Color]]) -> Calcio 5-Tier Wardrobe Brown Maple | H13: =VLOOKUP(Table1[[#This Row],[MTP SKU]],'MTP SKUs - Master Data'!A:D,3,0) -> Calcio 5-Tier Wardrobe | K13: B0F91468XK | L13: WCLHCARGJE9DFNG7 | M13: LSTWCLHCARGJE9DFNG78VG4UU | N13: FVSGCB11BR51517 | O13: FN2260673-S-PM39235 | P13: FN2260673-S-WH41218 | Q13: #N/A
A14: SR-BKN-TM | B14: =IFERROR(VLOOKUP(Table1[[#This Row],[Seller SKU]],'[1]FG Snapshot (V2)'!$A:$B,2,0),"AR") -> Y | C14: =IFERROR(VLOOKUP(Table1[[#This Row],[Seller SKU]],'[1]FG Snapshot (V2)'!$A:$E,5,0),"AR") -> 15 | D14: SR-BKN-T | E14: =VLOOKUP(Table1[[#This Row],[MTP SKU]],'MTP SKUs - Master Data'!A:D,3,0) -> Brooklyn Tall Shoe Rack | F14: Brown Maple | G14: =_xlfn.CONCAT(Table1[[#This Row],[MTP Name]]," ",Table1[[#This Row],[ Child Color]]) -> Brooklyn Tall Shoe Rack Brown Maple | H14: =VLOOKUP(Table1[[#This Row],[MTP SKU]],'MTP SKUs - Master Data'!A:D,3,0) -> Brooklyn Tall Shoe Rack | J14: #N/A | K14: B0DSQ5MH6T | L14: SHKH95M3REHRAZHJ | M14: LSTSHKH95M3REHRAZHJSNG9HZ | N14: FVSGSR11BM51568 | O14: FN2260661-S-PM39235 | P14: FN2260661-S-WH41218 | Q14: 34399229
A15: TU-SKD-LF | B15: =IFERROR(VLOOKUP(Table1[[#This Row],[Seller SKU]],'[1]FG Snapshot (V2)'!$A:$B,2,0),"AR") -> YD | C15: =IFERROR(VLOOKUP(Table1[[#This Row],[Seller SKU]],'[1]FG Snapshot (V2)'!$A:$E,5,0),"AR") -> 27 | D15: TU-SKD | E15: =VLOOKUP(Table1[[#This Row],[MTP SKU]],'MTP SKUs - Master Data'!A:D,3,0) -> Skiddo TV Unit | F15: Walnut & White | G15: =_xlfn.CONCAT(Table1[[#This Row],[MTP Name]]," ",Table1[[#This Row],[ Child Color]]) -> Skiddo TV Unit Walnut & White | H15: =VLOOKUP(Table1[[#This Row],[MTP SKU]],'MTP SKUs - Master Data'!A:D,3,0) -> Skiddo TV Unit | J15: X0023REYJJ | K15: B0BCZ699P2 | L15: TVUGG2FKGHH8SXA9 | M15: LSTTVUGG2FKGHH8SXA9QIZKRE | N15: FVTBAV33BR70799 | O15: FN2087161-S-PM39235 | P15: FN2087161-S-WH41218 | Q15: 34399021
A16: SR-CLM-3M | B16: =IFERROR(VLOOKUP(Table1[[#This Row],[Seller SKU]],'[1]FG Snapshot (V2)'!$A:$B,2,0),"AR") -> y | C16: =IFERROR(VLOOKUP(Table1[[#This Row],[Seller SKU]],'[1]FG Snapshot (V2)'!$A:$E,5,0),"AR") -> 6 | D16: SR-CLM-3 | E16: =VLOOKUP(Table1[[#This Row],[MTP SKU]],'MTP SKUs - Master Data'!A:D,3,0) -> Carlem 3 Door Shoe Rack | F16: Brown Maple | G16: =_xlfn.CONCAT(Table1[[#This Row],[MTP Name]]," ",Table1[[#This Row],[ Child Color]]) -> Carlem 3 Door Shoe Rack Brown Maple | H16: =VLOOKUP(Table1[[#This Row],[MTP SKU]],'MTP SKUs - Master Data'!A:D,3,0) -> Carlem 3 Door Shoe Rack | J16: X0022LYPC7 | K16: B0CR69LX8T | L16: CSDGWZYSKGJSWHK6 | M16: LSTCSDGWZYSKGJSWHK6YBM4FU | N16: FVSGBR33BR72391 | O16: FN2166587-S-PM39235 | P16: FN2166587-S-WH41218 | Q16: 34399038
A17: W-MLT-MMF | B17: =IFERROR(VLOOKUP(Table1[[#This Row],[Seller SKU]],'[1]FG Snapshot (V2)'!$A:$B,2,0),"AR") -> Y | C17: =IFERROR(VLOOKUP(Table1[[#This Row],[Seller SKU]],'[1]FG Snapshot (V2)'!$A:$E,5,0),"AR") -> 24 | D17: W-MLT-M | E17: =VLOOKUP(Table1[[#This Row],[MTP SKU]],'MTP SKUs - Master Data'!A:D,3,0) -> Maltein Mini Wardrobe | F17: Brown Maple & White | G17: =_xlfn.CONCAT(Table1[[#This Row],[MTP Name]]," ",Table1[[#This Row],[ Child Color]]) -> Maltein Mini Wardrobe Brown Maple & White | H17: =VLOOKUP(Table1[[#This Row],[MTP SKU]],'MTP SKUs - Master Data'!A:D,3,0) -> Maltein Mini Wardrobe | K17: B0F8ZQGWZM | L17: WCLHC8TZMCYUGJ2H | M17: LSTWCLHC8TZMCYUGJ2HGRGYQT | N17: FVSGCB11BW51521 | O17: FN2260677-S-PM39235 | P17: FN2260677-S-WH41218 | Q17: #N/A
A18: TU-WBM-STMF | B18: =IFERROR(VLOOKUP(Table1[[#This Row],[Seller SKU]],'[1]FG Snapshot (V2)'!$A:$B,2,0),"AR") -> Y | C18: =IFERROR(VLOOKUP(Table1[[#This Row],[Seller SKU]],'[1]FG Snapshot (V2)'!$A:$E,5,0),"AR") -> 10 | D18: TU-WBM-ST | E18: =VLOOKUP(Table1[[#This Row],[MTP SKU]],'MTP SKUs - Master Data'!A:D,3,0) -> Wilbrome Mini TV Unit | F18: Brown Maple & White | G18: =_xlfn.CONCAT(Table1[[#This Row],[MTP Name]]," ",Table1[[#This Row],[ Child Color]]) -> Wilbrome Mini TV Unit Brown Maple & White | H18: =VLOOKUP(Table1[[#This Row],[MTP SKU]],'MTP SKUs - Master Data'!A:D,3,0) -> Wilbrome Mini TV Unit | J18: #N/A | K18: B0DSQ3TL2Q | L18: TVUH8GZ2FZTB4FXF | M18: LSTTVUH8GZ2FZTB4FXFINMHZF | N18: FVSGAV11BW51548 | O18: FN2229405-S-PM39235 | P18: FN2229405-S-WH41218 | Q18: #N/A
A19: SR-MVS-IM | B19: =IFERROR(VLOOKUP(Table1[[#This Row],[Seller SKU]],'[1]FG Snapshot (V2)'!$A:$B,2,0),"AR") -> Y | C19: =IFERROR(VLOOKUP(Table1[[#This Row],[Seller SKU]],'[1]FG Snapshot (V2)'!$A:$E,5,0),"AR") -> 20 | D19: SR-MVS-I | E19: =VLOOKUP(Table1[[#This Row],[MTP SKU]],'MTP SKUs - Master Data'!A:D,3,0) -> Mavis Seating Shoe Rack | F19: Brown Maple | G19: =_xlfn.CONCAT(Table1[[#This Row],[MTP Name]]," ",Table1[[#This Row],[ Child Color]]) -> Mavis Seating Shoe Rack Brown Maple | H19: =VLOOKUP(Table1[[#This Row],[MTP SKU]],'MTP SKUs - Master Data'!A:D,3,0) -> Mavis Seating Shoe Rack | K19: B0FBM1HTL7 | L19: SHKHCSGK2HQ3ZUPD | M19: LSTSHKHCSGK2HQ3ZUPDK2V99U | N19: FVSGSR11BM51571 | O19: FN2260663-S-PM39235 | P19: FN2260663-S-WH41218 | Q19: 35524081
A20: SR-KPN-MF | B20: =IFERROR(VLOOKUP(Table1[[#This Row],[Seller SKU]],'[1]FG Snapshot (V2)'!$A:$B,2,0),"AR") -> Y | C20: =IFERROR(VLOOKUP(Table1[[#This Row],[Seller SKU]],'[1]FG Snapshot (V2)'!$A:$E,5,0),"AR") -> 22 | D20: SR-KPN | E20: =VLOOKUP(Table1[[#This Row],[MTP SKU]],'MTP SKUs - Master Data'!A:D,3,0) -> Kaspen Shoe Rack | F20: Brown Maple & White | G20: =_xlfn.CONCAT(Table1[[#This Row],[MTP Name]]," ",Table1[[#This Row],[ Child Color]]) -> Kaspen Shoe Rack Brown Maple & White | H20: =VLOOKUP(Table1[[#This Row],[MTP SKU]],'MTP SKUs - Master Data'!A:D,3,0) -> Kaspen Shoe Rack | J20: X001YXTP9H | K20: B0CJML27W6 | L20: SHKGUJF3UF2DGWVH | M20: LSTSHKGUJF3UF2DGWVHCMW77H | N20: FVSGSR33BR32753 | O20: FN2152510-S-PM39235 | P20: FN2152510-S-WH41218 | Q20: 34399166
A21: TU-FL-FW | B21: =IFERROR(VLOOKUP(Table1[[#This Row],[Seller SKU]],'[1]FG Snapshot (V2)'!$A:$B,2,0),"AR") -> Y | C21: =IFERROR(VLOOKUP(Table1[[#This Row],[Seller SKU]],'[1]FG Snapshot (V2)'!$A:$E,5,0),"AR") -> 11 | D21: TU-FL | E21: =VLOOKUP(Table1[[#This Row],[MTP SKU]],'MTP SKUs - Master Data'!A:D,3,0) -> Fenily TV Unit | F21: Wenge | G21: =_xlfn.CONCAT(Table1[[#This Row],[MTP Name]]," ",Table1[[#This Row],[ Child Color]]) -> Fenily TV Unit Wenge | H21: =VLOOKUP(Table1[[#This Row],[MTP SKU]],'MTP SKUs - Master Data'!A:D,3,0) -> Fenily TV Unit | J21: #N/A | K21: B09XJ3Y86J | L21: TVUH4MFSZKDU3XHM | M21: LSTTVUH4MFSZKDU3XHMCHDSCE | N21: FVSGAV33WW20528 | O21: FN1987991-S-PM39235 | P21: FN1987991-S-WH41218 | Q21: 34399237
A22: SR-MVS-ITM | B22: =IFERROR(VLOOKUP(Table1[[#This Row],[Seller SKU]],'[1]FG Snapshot (V2)'!$A:$B,2,0),"AR") -> Y | C22: =IFERROR(VLOOKUP(Table1[[#This Row],[Seller SKU]],'[1]FG Snapshot (V2)'!$A:$E,5,0),"AR") -> 3 | D22: SR-MVS-IT | E22: =VLOOKUP(Table1[[#This Row],[MTP SKU]],'MTP SKUs - Master Data'!A:D,3,0) -> Mavis Combo Shoe Rack | F22: Brown Maple | G22: =_xlfn.CONCAT(Table1[[#This Row],[MTP Name]]," ",Table1[[#This Row],[ Child Color]]) -> Mavis Combo Shoe Rack Brown Maple | H22: =VLOOKUP(Table1[[#This Row],[MTP SKU]],'MTP SKUs - Master Data'!A:D,3,0) -> Mavis Combo Shoe Rack | K22: B0F91299Q2 | L22: SHKHCAT3GDMYGRFN | M22: LSTSHKHCAT3GDMYGRFNDS6X1K | N22: FVSGSR11BM51572 | O22: FN2260664-S-PM39235 | P22: FN2260664-S-WH41218 | Q22: 35524079
A23: TU-BKY-STM | B23: =IFERROR(VLOOKUP(Table1[[#This Row],[Seller SKU]],'[1]FG Snapshot (V2)'!$A:$B,2,0),"AR") -> Y | C23: =IFERROR(VLOOKUP(Table1[[#This Row],[Seller SKU]],'[1]FG Snapshot (V2)'!$A:$E,5,0),"AR") -> 23 | D23: TU-BKY-ST | E23: =VLOOKUP(Table1[[#This Row],[MTP SKU]],'MTP SKUs - Master Data'!A:D,3,0) -> Blesky Mini TV Unit | F23: Brown Maple | G23: =_xlfn.CONCAT(Table1[[#This Row],[MTP Name]]," ",Table1[[#This Row],[ Child Color]]) -> Blesky Mini TV Unit Brown Maple | H23: =VLOOKUP(Table1[[#This Row],[MTP SKU]],'MTP SKUs - Master Data'!A:D,3,0) -> Blesky Mini TV Unit | J23: #N/A | K23: B0DSQ19SZT | L23: TVUH8GYTFPGJXSNX | M23: LSTTVUH8GYTFPGJXSNX003FCA | N23: FVSGAV11BM51539 | O23: FN2229399-S-PM39235 | P23: FN2229399-S-WH41218 | Q23: 34399093
A24: SR-BKN-M | B24: =IFERROR(VLOOKUP(Table1[[#This Row],[Seller SKU]],'[1]FG Snapshot (V2)'!$A:$B,2,0),"AR") -> Y | C24: =IFERROR(VLOOKUP(Table1[[#This Row],[Seller SKU]],'[1]FG Snapshot (V2)'!$A:$E,5,0),"AR") -> 50 | D24: SR-BKN-2 | E24: =VLOOKUP(Table1[[#This Row],[MTP SKU]],'MTP SKUs - Master Data'!A:D,3,0) -> Brooklyn Shoe Rack | F24: Brown Maple | G24: =_xlfn.CONCAT(Table1[[#This Row],[MTP Name]]," ",Table1[[#This Row],[ Child Color]]) -> Brooklyn Shoe Rack Brown Maple | H24: =VLOOKUP(Table1[[#This Row],[MTP SKU]],'MTP SKUs - Master Data'!A:D,3,0) -> Brooklyn Shoe Rack | J24: X001YXXSTF | K24: B0CP7G5QDT | L24: SHKH7GBQ3Y5UGHY6 | M24: LSTSHKH7GBQ3Y5UGHY6YCUBOR | N24: FVSGSR33BR32751 | O24: FN2166555-S-PM39235 | P24: FN2166555-S-WH41218 | Q24: 34399032
A25: S-PTE-M | B25: =IFERROR(VLOOKUP(Table1[[#This Row],[Seller SKU]],'[1]FG Snapshot (V2)'!$A:$B,2,0),"AR") -> y | C25: =IFERROR(VLOOKUP(Table1[[#This Row],[Seller SKU]],'[1]FG Snapshot (V2)'!$A:$E,5,0),"AR") -> 17 | D25: S-PTE | E25: =VLOOKUP(Table1[[#This Row],[MTP SKU]],'MTP SKUs - Master Data'!A:D,3,0) -> Petree Wall Shelve | F25: Brown Maple | G25: =_xlfn.CONCAT(Table1[[#This Row],[MTP Name]]," ",Table1[[#This Row],[ Child Color]]) -> Petree Wall Shelve Brown Maple | H25: =VLOOKUP(Table1[[#This Row],[MTP SKU]],'MTP SKUs - Master Data'!A:D,3,0) -> Petree Wall Shelve | J25: X001XQD9H9 | K25: B0CQNX8LKS | L25: BSFGWYJSA2HHHPHT | M25: LSTBSFGWYJSA2HHHPHTYDE7VD | N25: FVSGWS33BR72396 | O25: DE2198506-S-PM39397 | P25: Not in WH | Q25: 29525078
A26: SR-CLE-MF | B26: =IFERROR(VLOOKUP(Table1[[#This Row],[Seller SKU]],'[1]FG Snapshot (V2)'!$A:$B,2,0),"AR") -> Y | C26: =IFERROR(VLOOKUP(Table1[[#This Row],[Seller SKU]],'[1]FG Snapshot (V2)'!$A:$E,5,0),"AR") -> 36 | D26: SR-CLE | E26: =VLOOKUP(Table1[[#This Row],[MTP SKU]],'MTP SKUs - Master Data'!A:D,3,0) -> Cylvie Shoe Rack | F26: Brown Maple & White | G26: =_xlfn.CONCAT(Table1[[#This Row],[MTP Name]]," ",Table1[[#This Row],[ Child Color]]) -> Cylvie Shoe Rack Brown Maple & White | H26: =VLOOKUP(Table1[[#This Row],[MTP SKU]],'MTP SKUs - Master Data'!A:D,3,0) -> Cylvie Shoe Rack | J26: X001YXXQJH | K26: B0CV33DPSP | L26: SHKGXUTFT7GNNTMQ | M26: LSTSHKGXUTFT7GNNTMQLWFGXU | N26: FVSGSR33BR32755 | O26: FN2194306-S-PM39235 | P26: FN2194306-S-WH41218 | Q26: 34399203
A27: TU-AYL-M | B27: =IFERROR(VLOOKUP(Table1[[#This Row],[Seller SKU]],'[1]FG Snapshot (V2)'!$A:$B,2,0),"AR") -> Y | C27: =IFERROR(VLOOKUP(Table1[[#This Row],[Seller SKU]],'[1]FG Snapshot (V2)'!$A:$E,5,0),"AR") -> 37 | D27: TU-AYL | E27: =VLOOKUP(Table1[[#This Row],[MTP SKU]],'MTP SKUs - Master Data'!A:D,3,0) -> Averyl TV Unit | F27: Brown Maple | G27: =_xlfn.CONCAT(Table1[[#This Row],[MTP Name]]," ",Table1[[#This Row],[ Child Color]]) -> Averyl TV Unit Brown Maple | H27: =VLOOKUP(Table1[[#This Row],[MTP SKU]],'MTP SKUs - Master Data'!A:D,3,0) -> Averyl TV Unit | J27: X001YODXTT | K27: B0CV3HL1JS | L27: TVUGXUTJUQHJ9KJS | M27: LSTTVUGXUTJUQHJ9KJSKLQSEQ | N27: FVTBAV33BR32711 | O27: FN2194313-S-PM39235 | P27: FN2194313-S-WH41218 | Q27: 34398996
A28: SR-KPN-FL | B28: =IFERROR(VLOOKUP(Table1[[#This Row],[Seller SKU]],'[1]FG Snapshot (V2)'!$A:$B,2,0),"AR") -> YD | C28: =IFERROR(VLOOKUP(Table1[[#This Row],[Seller SKU]],'[1]FG Snapshot (V2)'!$A:$E,5,0),"AR") -> 49 | D28: SR-KPN | E28: =VLOOKUP(Table1[[#This Row],[MTP SKU]],'MTP SKUs - Master Data'!A:D,3,0) -> Kaspen Shoe Rack | F28: Walnut & White | G28: =_xlfn.CONCAT(Table1[[#This Row],[MTP Name]]," ",Table1[[#This Row],[ Child Color]]) -> Kaspen Shoe Rack Walnut & White | H28: =VLOOKUP(Table1[[#This Row],[MTP SKU]],'MTP SKUs - Master Data'!A:D,3,0) -> Kaspen Shoe Rack | J28: X001YXTP97 | K28: B09WR9FZXZ | L28: CSDGDC3QJKBD2EFA | M28: LSTCSDGDC3QJKBD2EFAJWVEYL | N28: FVSGSR33WW20615 | O28: FN1991916-S-PM39235 | P28: FN1991916-S-WH41218 | Q28: 34399025
A29: SR-BKN-HM | B29: =IFERROR(VLOOKUP(Table1[[#This Row],[Seller SKU]],'[1]FG Snapshot (V2)'!$A:$B,2,0),"AR") -> Y | C29: =IFERROR(VLOOKUP(Table1[[#This Row],[Seller SKU]],'[1]FG Snapshot (V2)'!$A:$E,5,0),"AR") -> 9 | D29: SR-BKN-H | E29: =VLOOKUP(Table1[[#This Row],[MTP SKU]],'MTP SKUs - Master Data'!A:D,3,0) -> Brooklyn Highline Shoe Rack | F29: Brown Maple | G29: =_xlfn.CONCAT(Table1[[#This Row],[MTP Name]]," ",Table1[[#This Row],[ Child Color]]) -> Brooklyn Highline Shoe Rack Brown Maple | H29: =VLOOKUP(Table1[[#This Row],[MTP SKU]],'MTP SKUs - Master Data'!A:D,3,0) -> Brooklyn Highline Shoe Rack | K29: B0F9139B7X | L29: SHKHCAS8YHF9HXMA | M29: LSTSHKHCAS8YHF9HXMAPBOC3L | N29: FVSGSR11BM51567 | O29: FN2260660-S-PM39235 | P29: FN2260660-S-WH41218 | Q29: 35524073
A30: TU-SKD-OF | B30: =IFERROR(VLOOKUP(Table1[[#This Row],[Seller SKU]],'[1]FG Snapshot (V2)'!$A:$B,2,0),"AR") -> NL | C30: =IFERROR(VLOOKUP(Table1[[#This Row],[Seller SKU]],'[1]FG Snapshot (V2)'!$A:$E,5,0),"AR") -> 73 | D30: TU-SKD | E30: =VLOOKUP(Table1[[#This Row],[MTP SKU]],'MTP SKUs - Master Data'!A:D,3,0) -> Skiddo TV Unit | F30: European Oak & White | G30: =_xlfn.CONCAT(Table1[[#This Row],[MTP Name]]," ",Table1[[#This Row],[ Child Color]]) -> Skiddo TV Unit European Oak & White | H30: =VLOOKUP(Table1[[#This Row],[MTP SKU]],'MTP SKUs - Master Data'!A:D,3,0) -> Skiddo TV Unit | K30: B0FNMKSVYJ | L30: TVUHH6GPYWDFP4HT | N30: #N/A | P30: Not in WH
A31: TU-FL-FL | B31: =IFERROR(VLOOKUP(Table1[[#This Row],[Seller SKU]],'[1]FG Snapshot (V2)'!$A:$B,2,0),"AR") -> YD | C31: =IFERROR(VLOOKUP(Table1[[#This Row],[Seller SKU]],'[1]FG Snapshot (V2)'!$A:$E,5,0),"AR") -> 29 | D31: TU-FL | E31: =VLOOKUP(Table1[[#This Row],[MTP SKU]],'MTP SKUs - Master Data'!A:D,3,0) -> Fenily TV Unit | F31: Walnut & White | G31: =_xlfn.CONCAT(Table1[[#This Row],[MTP Name]]," ",Table1[[#This Row],[ Child Color]]) -> Fenily TV Unit Walnut & White | H31: =VLOOKUP(Table1[[#This Row],[MTP SKU]],'MTP SKUs - Master Data'!A:D,3,0) -> Fenily TV Unit | J31: #N/A | K31: B09XJ24NG8 | L31: TVUH7RE5XBS4HBXR | M31: LSTTVUH7RE5XBS4HBXRD9VHIU | N31: FVSGAV33WW20527 | O31: FN1991938-S-PM39235 | P31: FN1991938-S-WH41218 | Q31: 34398994
A32: TU-SKDL-MF | B32: =IFERROR(VLOOKUP(Table1[[#This Row],[Seller SKU]],'[1]FG Snapshot (V2)'!$A:$B,2,0),"AR") -> Y | C32: =IFERROR(VLOOKUP(Table1[[#This Row],[Seller SKU]],'[1]FG Snapshot (V2)'!$A:$E,5,0),"AR") -> 45 | D32: TU-SKDL | E32: =VLOOKUP(Table1[[#This Row],[MTP SKU]],'MTP SKUs - Master Data'!A:D,3,0) -> Skiddo Lite TV Unit | F32: Brown Maple & White | G32: =_xlfn.CONCAT(Table1[[#This Row],[MTP Name]]," ",Table1[[#This Row],[ Child Color]]) -> Skiddo Lite TV Unit Brown Maple & White | H32: =VLOOKUP(Table1[[#This Row],[MTP SKU]],'MTP SKUs - Master Data'!A:D,3,0) -> Skiddo Lite TV Unit | K32: B0CDLQ8B41 | L32: TVUHDUEWGYRCH3GH | M32: LSTTVUHDUEWGYRCH3GHMOH1VQ | N32: FVSGAV11BW51546 | O32: FN2260668-S-PM39235 | P32: FN2260668-S-WH41218 | Q32: 35524076
A33: TU-HMD-MF | B33: =IFERROR(VLOOKUP(Table1[[#This Row],[Seller SKU]],'[1]FG Snapshot (V2)'!$A:$B,2,0),"AR") -> y | C33: =IFERROR(VLOOKUP(Table1[[#This Row],[Seller SKU]],'[1]FG Snapshot (V2)'!$A:$E,5,0),"AR") -> 30 | D33: TU-HMD | E33: =VLOOKUP(Table1[[#This Row],[MTP SKU]],'MTP SKUs - Master Data'!A:D,3,0) -> Harmond TV Unit | F33: Brown Maple & White | G33: =_xlfn.CONCAT(Table1[[#This Row],[MTP Name]]," ",Table1[[#This Row],[ Child Color]]) -> Harmond TV Unit Brown Maple & White | H33: =VLOOKUP(Table1[[#This Row],[MTP SKU]],'MTP SKUs - Master Data'!A:D,3,0) -> Harmond TV Unit | J33: X001YXXODZ | K33: B07N41C315 | L33: TVUGVHFNDSJJDECC | M33: LSTTVUGVHFNDSJJDECCOUFRNZ | N33: FVTBAV33BR32709 | O33: FN2152520-S-PM39235 | P33: FN2152520-S-WH41218 | Q33: 34399103
A34: DC-MYN-STMF | B34: =IFERROR(VLOOKUP(Table1[[#This Row],[Seller SKU]],'[1]FG Snapshot (V2)'!$A:$B,2,0),"AR") -> y | C34: =IFERROR(VLOOKUP(Table1[[#This Row],[Seller SKU]],'[1]FG Snapshot (V2)'!$A:$E,5,0),"AR") -> 48 | D34: DC-MYN-ST | E34: =VLOOKUP(Table1[[#This Row],[MTP SKU]],'MTP SKUs - Master Data'!A:D,3,0) -> Mayrone Standard Chest of Drawer | F34: Brown Maple & White | G34: =_xlfn.CONCAT(Table1[[#This Row],[MTP Name]]," ",Table1[[#This Row],[ Child Color]]) -> Mayrone Standard Chest of Drawer Brown Maple & White | H34: =VLOOKUP(Table1[[#This Row],[MTP SKU]],'MTP SKUs - Master Data'!A:D,3,0) -> Mayrone Standard Chest of Drawer | J34: #N/A | K34: B0CJCJJJ54 | L34: CSDGUGVTFGESHDZU | M34: LSTCSDGUGVTFGESHDZUEAHMTI | N34: FVSGDR33BR32696 | O34: FN2135042-S-PM39235 | P34: FN2135042-S-WH41218 | Q34: 35522194
A35: B-MLT-D30TM | B35: =IFERROR(VLOOKUP(Table1[[#This Row],[Seller SKU]],'[1]FG Snapshot (V2)'!$A:$B,2,0),"AR") -> Y | C35: =IFERROR(VLOOKUP(Table1[[#This Row],[Seller SKU]],'[1]FG Snapshot (V2)'!$A:$E,5,0),"AR") -> 18 | D35: B-MLT-D30T | E35: =VLOOKUP(Table1[[#This Row],[MTP SKU]],'MTP SKUs - Master Data'!A:D,3,0) -> Maltein Diwan 30" with Storage Bed | F35: Brown Maple | G35: =_xlfn.CONCAT(Table1[[#This Row],[MTP Name]]," ",Table1[[#This Row],[ Child Color]]) -> Maltein Diwan 30" with Storage Bed Brown Maple | H35: =VLOOKUP(Table1[[#This Row],[MTP SKU]],'MTP SKUs - Master Data'!A:D,3,0) -> Maltein Diwan 30" with Storage Bed | K35: B0FGTVTZFS | L35: BDDHDTC8CFHQU3Z8 | M35: LSTBDDHDTC8CFHQU3Z8Z07AT5 | N35: FVBDST11BR51511 | O35: FN2260655-S-PM39235 | P35: FN2260655-S-WH41218 | Q35: #N/A
A36: SR-MVS-TM | B36: =IFERROR(VLOOKUP(Table1[[#This Row],[Seller SKU]],'[1]FG Snapshot (V2)'!$A:$B,2,0),"AR") -> Y | C36: =IFERROR(VLOOKUP(Table1[[#This Row],[Seller SKU]],'[1]FG Snapshot (V2)'!$A:$E,5,0),"AR") -> 60 | D36: SR-MVS-T | E36: =VLOOKUP(Table1[[#This Row],[MTP SKU]],'MTP SKUs - Master Data'!A:D,3,0) -> Mavis Tall Shoe Rack | F36: Brown Maple | G36: =_xlfn.CONCAT(Table1[[#This Row],[MTP Name]]," ",Table1[[#This Row],[ Child Color]]) -> Mavis Tall Shoe Rack Brown Maple | H36: =VLOOKUP(Table1[[#This Row],[MTP SKU]],'MTP SKUs - Master Data'!A:D,3,0) -> Mavis Tall Shoe Rack | K36: B0FBM7C35S | L36: SHKHCSGQGTHDWQP8 | M36: LSTSHKHCSGQGTHDWQP8G3V4M2 | N36: FVSGSR11BM51573 | O36: FN2260665-S-PM39235 | P36: FN2260665-S-WH41218 | Q36: 35524078
A37: SR-CLM-2M | B37: =IFERROR(VLOOKUP(Table1[[#This Row],[Seller SKU]],'[1]FG Snapshot (V2)'!$A:$B,2,0),"AR") -> y | C37: =IFERROR(VLOOKUP(Table1[[#This Row],[Seller SKU]],'[1]FG Snapshot (V2)'!$A:$E,5,0),"AR") -> 28 | D37: SR-CLM-2 | E37: =VLOOKUP(Table1[[#This Row],[MTP SKU]],'MTP SKUs - Master Data'!A:D,3,0) -> Carlem 2 Door Shoe Rack | F37: Brown Maple | G37: =_xlfn.CONCAT(Table1[[#This Row],[MTP Name]]," ",Table1[[#This Row],[ Child Color]]) -> Carlem 2 Door Shoe Rack Brown Maple | H37: =VLOOKUP(Table1[[#This Row],[MTP SKU]],'MTP SKUs - Master Data'!A:D,3,0) -> Carlem 2 Door Shoe Rack | J37: X001YAPESL | K37: B0CR6B1KPV | L37: CSDGXYYPHCGGZQWS | M37: LSTCSDGXYYPHCGGZQWSZANXDC | N37: FVSGBR33BR72390 | O37: FN2166588-S-PM39235 | P37: FN2166588-S-WH41218 | Q37: 34399190
A38: PU-SUB-OF | B38: =IFERROR(VLOOKUP(Table1[[#This Row],[Seller SKU]],'[1]FG Snapshot (V2)'!$A:$B,2,0),"AR") -> NL | C38: =IFERROR(VLOOKUP(Table1[[#This Row],[Seller SKU]],'[1]FG Snapshot (V2)'!$A:$E,5,0),"AR") -> 26 | D38: PU-SUB | E38: =VLOOKUP(Table1[[#This Row],[MTP SKU]],'MTP SKUs - Master Data'!A:D,3,0) -> Shubh Pooja Unit Temple | F38: European Oak | G38: =_xlfn.CONCAT(Table1[[#This Row],[MTP Name]]," ",Table1[[#This Row],[ Child Color]]) -> Shubh Pooja Unit Temple European Oak | H38: =VLOOKUP(Table1[[#This Row],[MTP SKU]],'MTP SKUs - Master Data'!A:D,3,0) -> Shubh Pooja Unit Temple | K38: B0FPR86F6F | L38: HTEHGGVNH77K924P | N38: #N/A | O38: KD2280090-S-PM39397 | P38: Not in WH
A39: TU-BKMT-M | B39: =IFERROR(VLOOKUP(Table1[[#This Row],[Seller SKU]],'[1]FG Snapshot (V2)'!$A:$B,2,0),"AR") -> Y | C39: =IFERROR(VLOOKUP(Table1[[#This Row],[Seller SKU]],'[1]FG Snapshot (V2)'!$A:$E,5,0),"AR") -> 31 | D39: TU-BKMT | E39: =VLOOKUP(Table1[[#This Row],[MTP SKU]],'MTP SKUs - Master Data'!A:D,3,0) -> Blesky Miltra Combo TV Unit | F39: Brown Maple | G39: =_xlfn.CONCAT(Table1[[#This Row],[MTP Name]]," ",Table1[[#This Row],[ Child Color]]) -> Blesky Miltra Combo TV Unit Brown Maple | H39: =VLOOKUP(Table1[[#This Row],[MTP SKU]],'MTP SKUs - Master Data'!A:D,3,0) -> Blesky Miltra Combo TV Unit | J39: #N/A | K39: B0DGCY3HW8 | L39: TVUH63FQ8JG2UPFD | M39: LSTTVUH63FQ8JG2UPFDVDFM6F | N39: FVSGAV11BM51537 | O39: FN2200967-S-PM39235 | P39: Not in WH | Q39: 34399085
A40: CT-LE-M | B40: =IFERROR(VLOOKUP(Table1[[#This Row],[Seller SKU]],'[1]FG Snapshot (V2)'!$A:$B,2,0),"AR") -> Y | C40: =IFERROR(VLOOKUP(Table1[[#This Row],[Seller SKU]],'[1]FG Snapshot (V2)'!$A:$E,5,0),"AR") -> 62 | D40: CT-LE | E40: =VLOOKUP(Table1[[#This Row],[MTP SKU]],'MTP SKUs - Master Data'!A:D,3,0) -> Leo Coffee Table | F40: Brown Maple | G40: =_xlfn.CONCAT(Table1[[#This Row],[MTP Name]]," ",Table1[[#This Row],[ Child Color]]) -> Leo Coffee Table Brown Maple | H40: =VLOOKUP(Table1[[#This Row],[MTP SKU]],'MTP SKUs - Master Data'!A:D,3,0) -> Leo Coffee Table | J40: #N/A | K40: B06WLNKHXC | L40: CFTH89D5BUVCGSSG | M40: LSTCFTH89D5BUVCGSSGQU1TLP | N40: FVTBCF11BR51533 | O40: FN2229387-S-PM39235 | P40: FN2229387-S-WH41218 | Q40: 34399215
...

Sheet Sheet1
A1: ASIN | B1: SKU | C1: PF | D1: UL | E1: Competitor URL | F1: Amazon Price | G1: Lowest competitor price | H1: SDF
A2: B0CT2ZMKGM | B2: =_xlfn.XLOOKUP(A2,'Child SKUs - Alias Master'!K:K,'Child SKUs - Alias Master'!A:A) -> TU-RYE-STMI | C2: =_xlfn.XLOOKUP(B2,'Child SKUs - Alias Master'!A:A,'Child SKUs - Alias Master'!O:O) -> FN2194318-S-PM39235 | D2: =_xlfn.XLOOKUP(B2,'Child SKUs - Alias Master'!A:A,'Child SKUs - Alias Master'!N:N) -> FVSGAV33BR50157 | E2: https://www.pepperfry.com/product/reyloye-tv-unit-in-brown-maple-beige-finish-2194318.html | F2: 3689 | G2: 3468 | H2: 3799
A3: B07D1KM4DJ | B3: =_xlfn.XLOOKUP(A3,'Child SKUs - Alias Master'!K:K,'Child SKUs - Alias Master'!A:A) -> SB-WA-WMW | C3: =_xlfn.XLOOKUP(B3,'Child SKUs - Alias Master'!A:A,'Child SKUs - Alias Master'!O:O) -> FN1991894-S-PM39235 | D3: =_xlfn.XLOOKUP(B3,'Child SKUs - Alias Master'!A:A,'Child SKUs - Alias Master'!N:N) -> FVSGBR33WN20587 | E3: https://www.pepperfry.com/product/walten-book-shelf-in-wenge-finish-1991894.html | F3: 1939 | G3: 1878 | H3: 1999
A4: B0CJCJJJ54 | B4: =_xlfn.XLOOKUP(A4,'Child SKUs - Alias Master'!K:K,'Child SKUs - Alias Master'!A:A) -> DC-MYN-STMF | C4: =_xlfn.XLOOKUP(B4,'Child SKUs - Alias Master'!A:A,'Child SKUs - Alias Master'!O:O) -> FN2135042-S-PM39235 | D4: =_xlfn.XLOOKUP(B4,'Child SKUs - Alias Master'!A:A,'Child SKUs - Alias Master'!N:N) -> FVSGDR33BR32696 | E4: https://www.flipkart.com/bluewud-engineered-wood-free-standing-chest-drawers/p/itm10b8893f55f33?pid=CSDGUGVTFGESHDZU&lid=LSTCSDGUGVTFGESHDZUOMOZGM&marketplace=FLIPKART&q=BLUEWUD+Chest+of+Drawers&store=wwe%2Fxdf%2Ffcg&srno=s_1_5&otracker=search&otracker1=search&fm=organic&iid=4ea4d803-99b2-4447-99c3-49140171c0be.CSDGUGVTFGESHDZU.SEARCH&ppt=hp&ppn=homepage&ssid=wxby8vkwuo0000001699037510339&qH=6fbc34d45828e909 | F4: 8829 | G4: 7799 | H4: 11599
A5: B0B8MXTLK2 | B5: =_xlfn.XLOOKUP(A5,'Child SKUs - Alias Master'!K:K,'Child SKUs - Alias Master'!A:A) -> W-AND-4NFW | C5: =_xlfn.XLOOKUP(B5,'Child SKUs - Alias Master'!A:A,'Child SKUs - Alias Master'!O:O) -> FN2027701-S-PM39235 | D5: =_xlfn.XLOOKUP(B5,'Child SKUs - Alias Master'!A:A,'Child SKUs - Alias Master'!N:N) -> FVSGSR33BR71093 | E5: https://www.pepperfry.com/product/andrie-4-door-wardrobe-in-wenge-and-white-finish-2027701.html | F5: 25219 | G5: 24988 | H5: 25999
A6: B09X1HTQYK | B6: =_xlfn.XLOOKUP(A6,'Child SKUs - Alias Master'!K:K,'Child SKUs - Alias Master'!A:A) -> CT-MT-ROW | C6: =_xlfn.XLOOKUP(B6,'Child SKUs - Alias Master'!A:A,'Child SKUs - Alias Master'!O:O) -> FN1991992-S-PM39235 | D6: =_xlfn.XLOOKUP(B6,'Child SKUs - Alias Master'!A:A,'Child SKUs - Alias Master'!N:N) -> FVTBCF33WN20642 | E6: https://www.flipkart.com/bluewud-mayrite-coffee-center-sofa-teapoy-console-table-set-living-room-home-engineered-wood/p/itmef82adee01408?pid=CFTGDCFRN4H4N8BW&lid=LSTCFTGDCFRN4H4N8BW1PKZVM&marketplace=FLIPKART&store=wwe%2Fki7%2Fot1&srno=b_9_334&otracker=browse&fm=organic&iid=5fd64004-5d69-4a34-8323-5990ce10504a.CFTGDCFRN4H4N8BW.SEARCH&ppt=None&ppn=None&ssid=9zttumtwa80000001724950377823 | F6: 2139 | G6: 1829 | H6: Matched
A7: B00PS6MFM2 | B7: =_xlfn.XLOOKUP(A7,'Child SKUs - Alias Master'!K:K,'Child SKUs - Alias Master'!A:A) -> RG-KH-SW-WB | C7: =_xlfn.XLOOKUP(B7,'Child SKUs - Alias Master'!A:A,'Child SKUs - Alias Master'!O:O) -> DE1994926-S-PM39397 | D7: =_xlfn.XLOOKUP(B7,'Child SKUs - Alias Master'!A:A,'Child SKUs - Alias Master'!N:N) -> #N/A | E7: https://www.flipkart.com/bluewud-skywood-wood-key-holder/p/itma45469a869ff2?pid=HOKE5EE9H83BFNUZ | F7: 299 | G7: 284 | H7: Corrected
A8: B0DFPPJ56P | B8: =_xlfn.XLOOKUP(A8,'Child SKUs - Alias Master'!K:K,'Child SKUs - Alias Master'!A:A) -> TU-DSK-M | C8: =_xlfn.XLOOKUP(B8,'Child SKUs - Alias Master'!A:A,'Child SKUs - Alias Master'!O:O) -> FN2200969-S-PM39235 | D8: =_xlfn.XLOOKUP(B8,'Child SKUs - Alias Master'!A:A,'Child SKUs - Alias Master'!N:N) -> FVSGAV11BM51541 | E8: https://www.pepperfry.com/product/duskin-tv-console-in-brown-maple-finish-2200969.html?type=clip&pos=5&total_result=211&fromId=5415&sort=sorting_score%7Cdesc&filter=%7C&cat=5415 | F8: 6399 | G8: 5618 | H8: 6599
A9: B06WRTMT7T | B9: =_xlfn.XLOOKUP(A9,'Child SKUs - Alias Master'!K:K,'Child SKUs - Alias Master'!A:A) -> SB-WA-W | C9: =_xlfn.XLOOKUP(B9,'Child SKUs - Alias Master'!A:A,'Child SKUs - Alias Master'!O:O) -> FN1988001-S-PM39235 | D9: =_xlfn.XLOOKUP(B9,'Child SKUs - Alias Master'!A:A,'Child SKUs - Alias Master'!N:N) -> FVSGBR33WN20586 | E9: http://www.pepperfry.com/product/walten-book-shelf-in-wenge-finish-with-5-tier-1988001.html | F9: 1939 | G9: 1918 | H9: 1999
A10: B0CJCLT2M9 | B10: =_xlfn.XLOOKUP(A10,'Child SKUs - Alias Master'!K:K,'Child SKUs - Alias Master'!A:A) -> DC-MYN-LAMF | C10: =_xlfn.XLOOKUP(B10,'Child SKUs - Alias Master'!A:A,'Child SKUs - Alias Master'!O:O) -> FN2135040-S-PM39235 | D10: =_xlfn.XLOOKUP(B10,'Child SKUs - Alias Master'!A:A,'Child SKUs - Alias Master'!N:N) -> FVSGDR33BR32697 | E10: https://www.pepperfry.com/product/mayrone-chest-of-drawers-in-brown-maple-frosty-finish-2135040.html | F10: 12909 | G10: 11738 | H10: 13299
A11: B09X1LH2VV | B11: =_xlfn.XLOOKUP(A11,'Child SKUs - Alias Master'!K:K,'Child SKUs - Alias Master'!A:A) -> CT-MT-RTW | C11: =_xlfn.XLOOKUP(B11,'Child SKUs - Alias Master'!A:A,'Child SKUs - Alias Master'!O:O) -> FN1991993-S-PM39235 | D11: =_xlfn.XLOOKUP(B11,'Child SKUs - Alias Master'!A:A,'Child SKUs - Alias Master'!N:N) -> FVTBCF33WN20643 | E11: https://www.flipkart.com/bluewud-mayrite-coffee-center-sofa-teapoy-console-table-set-living-room-home-engineered-wood/p/itm0589afd138d61?pid=CFTGDCFVN5C2DDN9 | F11: 1899 | G11: 1659 | H11: Corrected
A12: B019K1OVJK | B12: =_xlfn.XLOOKUP(A12,'Child SKUs - Alias Master'!K:K,'Child SKUs - Alias Master'!A:A) -> SB-AA-WD | C12: =_xlfn.XLOOKUP(B12,'Child SKUs - Alias Master'!A:A,'Child SKUs - Alias Master'!O:O) -> DE2231304-S-PM39397 | D12: =_xlfn.XLOOKUP(B12,'Child SKUs - Alias Master'!A:A,'Child SKUs - Alias Master'!N:N) -> FVSGCB33WG25113 | E12: https://www.urbanladder.com/products/bluewud-aaron-engineered-wood-multipurpose-wall-decor-shelf-display-rack-wenge-fvxxcb33wg25113?sku=FVSGCB33WG25113&src=subcat | F12: 609 | G12: 549 | H12: 609
A13: B0DG98BKCP | B13: =_xlfn.XLOOKUP(A13,'Child SKUs - Alias Master'!K:K,'Child SKUs - Alias Master'!A:A) -> SB-JMY-M | C13: =_xlfn.XLOOKUP(B13,'Child SKUs - Alias Master'!A:A,'Child SKUs - Alias Master'!O:O) -> FN2200963-S-PM39235 | D13: =_xlfn.XLOOKUP(B13,'Child SKUs - Alias Master'!A:A,'Child SKUs - Alias Master'!N:N) -> FVSGBR11BM51550 | E13: https://www.pepperfry.com/product/jameye-bookshelf-in-brown-maple-finish-2200963.html?type=clip&pos=8&total_result=205&fromId=22&sort=sorting_score%7Cdesc&filter=%7C&cat=22 | F13: 4469 | G13: 3948 | H13: 4599
A14: B09T3FKXLG | B14: =_xlfn.XLOOKUP(A14,'Child SKUs - Alias Master'!K:K,'Child SKUs - Alias Master'!A:A) -> S-GRB-W | C14: =_xlfn.XLOOKUP(B14,'Child SKUs - Alias Master'!A:A,'Child SKUs - Alias Master'!O:O) -> DE1994921-S-PM39397 | D14: =_xlfn.XLOOKUP(B14,'Child SKUs - Alias Master'!A:A,'Child SKUs - Alias Master'!N:N) -> FVSGCB33WG25088 | E14: https://www.flipkart.com/bluewud-grubbin-particle-board-wall-shelf/p/itm9229b4f390e59?pid=RSFGBTHYAPHPTHAG&lid=LSTRSFGBTHYAPHPTHAGXTS9WV&marketplace=FLIPKART&store=arb%2Fa77%2Fvk7&srno=b_1_35&otracker=browse&fm=organic&iid=8f1e3279-9035-4804-aecb-59df41f5f06c.RSFGBTHYAPHPTHAG.SEARCH&ppt=browse&ppn=browse&ssid=fztydgbkj40000001670325614437 | F14: 1269 | G14: 1129 | H14: Corrected
A15: B00IPAT2G0 | B15: =_xlfn.XLOOKUP(A15,'Child SKUs - Alias Master'!K:K,'Child SKUs - Alias Master'!A:A) -> RG-KH-SW-W21 | C15: =_xlfn.XLOOKUP(B15,'Child SKUs - Alias Master'!A:A,'Child SKUs - Alias Master'!O:O) -> DE1994923-S-PM39397 | D15: =_xlfn.XLOOKUP(B15,'Child SKUs - Alias Master'!A:A,'Child SKUs - Alias Master'!N:N) -> #N/A | E15: https://www.flipkart.com/bluewud-skywood-wall-mount-key-chain-holder-key-organizer-stand-wood-holder/p/itm069d07ce6a597?pid=HOKE5EE9E2TPEYFY&lid=LSTHOKE5EE9E2TPEYFYBVMF9C&marketplace=FLIPKART&store=arb%2Fa77%2F8js&srno=b_14_557&otracker=browse&iid=en_xKoXMve-ZeGNGCjlWd7bcWnQnyeWnH684UQ3K_ozavMaHRU0Fk5WCr9go3AtA3Tx8pxqxel11tA4ZvEUUAuVAQ%3D%3D&ssid=11exr99do00000001737521747682 | F15: 1169 | G15: 947 | H15: Corrected

Sheet MTP SKUs - Master Data
A1: MTP SKU | B1: MTP.chk | C1: Master MTP Product Name | D1: MRP | E1: CHP | F1: U.DP | G1: MOQ
A2: SR-CLM-T | B2: Y | C2: Carlem Tall Design Shoe Rack | D2: =VLOOKUP(A2,[2]MTP!$A:$B,2,0) -> 10199 | E2: =VLOOKUP(A2,[2]MTP!$A:$AM,39,0) -> 7688.3676 | F2: =VLOOKUP(A2,[2]MTP!$A:$E,5,0) -> 7599 | G2: =VLOOKUP(A2,[2]MTP!$A:$AO,41,0) -> 1
A3: TU-WBM | B3: Y | C3: Wilbrome TV Unit | D3: =VLOOKUP(A3,[2]MTP!$A:$B,2,0) -> 10799 | E3: =VLOOKUP(A3,[2]MTP!$A:$AM,39,0) -> 6526.573 | F3: =VLOOKUP(A3,[2]MTP!$A:$E,5,0) -> 6299 | G3: =VLOOKUP(A3,[2]MTP!$A:$AO,41,0) -> 1
A4: TU-SKD | B4: Y | C4: Skiddo TV Unit | D4: =VLOOKUP(A4,[2]MTP!$A:$B,2,0) -> 9599 | E4: =VLOOKUP(A4,[2]MTP!$A:$AM,39,0) -> 5437.9902 | F4: =VLOOKUP(A4,[2]MTP!$A:$E,5,0) -> 4999 | G4: =VLOOKUP(A4,[2]MTP!$A:$AO,41,0) -> 1
A5: TU-BKY | B5: Y | C5: Blesky TV Unit | D5: =VLOOKUP(A5,[2]MTP!$A:$B,2,0) -> 8999 | E5: =VLOOKUP(A5,[2]MTP!$A:$AM,39,0) -> 6379.019 | F5: =VLOOKUP(A5,[2]MTP!$A:$E,5,0) -> 6599 | G5: =VLOOKUP(A5,[2]MTP!$A:$AO,41,0) -> 1
A6: ST-CBN-LS | B6: Y | C6: Corbyn L-Shape Study Table | D6: =VLOOKUP(A6,[2]MTP!$A:$B,2,0) -> 6599 | E6: =VLOOKUP(A6,[2]MTP!$A:$AM,39,0) -> 4940.5038 | F6: =VLOOKUP(A6,[2]MTP!$A:$E,5,0) -> 5099 | G6: =VLOOKUP(A6,[2]MTP!$A:$AO,41,0) -> 1
A7: TU-BKMT | B7: Y | C7: Blesky Miltra Combo TV Unit | D7: =VLOOKUP(A7,[2]MTP!$A:$B,2,0) -> 15799 | E7: =VLOOKUP(A7,[2]MTP!$A:$AM,39,0) -> 9664.8641 | F7: =VLOOKUP(A7,[2]MTP!$A:$E,5,0) -> 9499 | G7: =VLOOKUP(A7,[2]MTP!$A:$AO,41,0) -> 1
A8: TU-DRN | B8: Y | C8: Darien TV Unit | D8: =VLOOKUP(A8,[2]MTP!$A:$B,2,0) -> 6199 | E8: =VLOOKUP(A8,[2]MTP!$A:$AM,39,0) -> 3605.7094 | F8: =VLOOKUP(A8,[2]MTP!$A:$E,5,0) -> 3899 | G8: =VLOOKUP(A8,[2]MTP!$A:$AO,41,0) -> 1
A9: TU-FL | B9: Y | C9: Fenily TV Unit | D9: =VLOOKUP(A9,[2]MTP!$A:$B,2,0) -> 25799 | E9: =VLOOKUP(A9,[2]MTP!$A:$AM,39,0) -> 17403.342 | F9: =VLOOKUP(A9,[2]MTP!$A:$E,5,0) -> 16299 | G9: =VLOOKUP(A9,[2]MTP!$A:$AO,41,0) -> 1
A10: SR-CLE | B10: Y | C10: Cylvie Shoe Rack | D10: =VLOOKUP(A10,[2]MTP!$A:$B,2,0) -> 8599 | E10: =VLOOKUP(A10,[2]MTP!$A:$AM,39,0) -> 4207.8826 | F10: =VLOOKUP(A10,[2]MTP!$A:$E,5,0) -> 4599 | G10: =VLOOKUP(A10,[2]MTP!$A:$AO,41,0) -> 1
A11: SR-BKN-2 | B11: Y | C11: Brooklyn Shoe Rack | D11: =VLOOKUP(A11,[2]MTP!$A:$B,2,0) -> 7999 | E11: =VLOOKUP(A11,[2]MTP!$A:$AM,39,0) -> 4560.5488 | F11: =VLOOKUP(A11,[2]MTP!$A:$E,5,0) -> 4999 | G11: =VLOOKUP(A11,[2]MTP!$A:$AO,41,0) -> 1
A12: SR-KPN | B12: Y | C12: Kaspen Shoe Rack | D12: =VLOOKUP(A12,[2]MTP!$A:$B,2,0) -> 12399 | E12: =VLOOKUP(A12,[2]MTP!$A:$AM,39,0) -> 7314.0546 | F12: =VLOOKUP(A12,[2]MTP!$A:$E,5,0) -> 7499 | G12: =VLOOKUP(A12,[2]MTP!$A:$AO,41,0) -> 1
A13: S-PTE | B13: Y | C13: Petree Wall Shelve | D13: =VLOOKUP(A13,[2]MTP!$A:$B,2,0) -> 4499 | E13: =VLOOKUP(A13,[2]MTP!$A:$AM,39,0) -> 2293.6646 | F13: =VLOOKUP(A13,[2]MTP!$A:$E,5,0) -> 2799 | G13: =VLOOKUP(A13,[2]MTP!$A:$AO,41,0) -> 1
... A245: SH-GTA | B245: Y | C245: Greta Metal Spice Rack | D245: =VLOOKUP(A245,[2]MTP!$A:$B,2,0) -> 2599 | E245: =VLOOKUP(A245,[2]MTP!$A:$AM,39,0) -> 1300.7139 | F245: =VLOOKUP(A245,[2]MTP!$A:$E,5,0) -> 999 | G245: =VLOOKUP(A245,[2]MTP!$A:$AO,41,0) -> 1
A246: S-TCW-10P2 | B246: DI | C246: Stellar Plus Wall Shelve | D246: =VLOOKUP(A246,[2]MTP!$A:$B,2,0) -> #N/A | F246: =VLOOKUP(A246,[2]MTP!$A:$E,5,0) -> #N/A | G246: =VLOOKUP(A246,[2]MTP!$A:$AO,41,0) -> #N/A
A247: RT-T1 | B247: DI | C247: Stellar Dressing Shelves | D247: =VLOOKUP(A247,[2]MTP!$A:$B,2,0) -> #N/A | F247: =VLOOKUP(A247,[2]MTP!$A:$E,5,0) -> #N/A | G247: =VLOOKUP(A247,[2]MTP!$A:$AO,41,0) -> #N/A
A248: RD-AW | B248: DI | C248: Riodesk Ace Laptop Table | D248: =VLOOKUP(A248,[2]MTP!$A:$B,2,0) -> #N/A | F248: =VLOOKUP(A248,[2]MTP!$A:$E,5,0) -> #N/A | G248: =VLOOKUP(A248,[2]MTP!$A:$AO,41,0) -> #N/A
A249: RT-T1 | B249: DI | C249: Stellar Dressing Shelves | D249: =VLOOKUP(A249,[2]MTP!$A:$B,2,0) -> #N/A | F249: =VLOOKUP(A249,[2]MTP!$A:$E,5,0) -> #N/A | G249: =VLOOKUP(A249,[2]MTP!$A:$AO,41,0) -> #N/A
A250: B-RVB-D30N | B250: RL | C250: Roverb Diwan 30 Inch Non Storage | D250: =VLOOKUP(A250,[2]MTP!$A:$B,2,0) -> #N/A | F250: =VLOOKUP(A250,[2]MTP!$A:$E,5,0) -> #N/A | G250: =VLOOKUP(A250,[2]MTP!$A:$AO,41,0) -> #N/A
A251: WA-FBA.P-D | B251: DI | C251: Febbora Wall art | D251: =VLOOKUP(A251,[2]MTP!$A:$B,2,0) -> #N/A | F251: =VLOOKUP(A251,[2]MTP!$A:$E,5,0) -> #N/A | G251: =VLOOKUP(A251,[2]MTP!$A:$AO,41,0) -> #N/A
A252: SR-WMO | B252: Y | C252: Wimzoe Shoe Rack | D252: =VLOOKUP(A252,[2]MTP!$A:$B,2,0) -> 10999 | E252: =VLOOKUP(A252,[2]MTP!$A:$AM,39,0) -> 7121.187 | F252: =VLOOKUP(A252,[2]MTP!$A:$E,5,0) -> 7199 | G252: =VLOOKUP(A252,[2]MTP!$A:$AO,41,0) -> 2
A253: PU-SUB | B253: Y | C253: Shubh Pooja Unit Temple | D253: =VLOOKUP(A253,[2]MTP!$A:$B,2,0) -> 9499 | E253: =VLOOKUP(A253,[2]MTP!$A:$AM,39,0) -> 5277.9783 | F253: =VLOOKUP(A253,[2]MTP!$A:$E,5,0) -> 5599 | G253: =VLOOKUP(A253,[2]MTP!$A:$AO,41,0) -> 3
A254: CH-ZLO-ME | B254: Y | C254: Zylo Medium Back Chair | D254: =VLOOKUP(A254,[2]MTP!$A:$B,2,0) -> 0 | F254: =VLOOKUP(A254,[2]MTP!$A:$E,5,0) -> 4599 | G254: =VLOOKUP(A254,[2]MTP!$A:$AO,41,0) -> 3
A255: CH-PLI-ME | B255: Y | C255: Polli Medium Back Chair | D255: =VLOOKUP(A255,[2]MTP!$A:$B,2,0) -> 0 | F255: =VLOOKUP(A255,[2]MTP!$A:$E,5,0) -> 4599 | G255: =VLOOKUP(A255,[2]MTP!$A:$AO,41,0) -> 3
A256: PU-SUB-ST | B256: Y | C256: Shubh Mini Pooja Temple | D256: =VLOOKUP(A256,[2]MTP!$A:$B,2,0) -> 4999 | F256: =VLOOKUP(A256,[2]MTP!$A:$E,5,0) -> 2999 | G256: =VLOOKUP(A256,[2]MTP!$A:$AO,41,0) -> 1
A257: ST-RDO-ST | B257: Y | C257: Radisso Mini Study Table | D257: =VLOOKUP(A257,[2]MTP!$A:$B,2,0) -> 4999 | F257: =VLOOKUP(A257,[2]MTP!$A:$E,5,0) -> 2899 | G257: =VLOOKUP(A257,[2]MTP!$A:$AO,41,0) -> 1
A258: PU-DRV | B258: Y | C258: Dhruv Wall Mount Pooja Unit | D258: =VLOOKUP(A258,[2]MTP!$A:$B,2,0) -> 4999 | F258: =VLOOKUP(A258,[2]MTP!$A:$E,5,0) -> 1299 | G258: =VLOOKUP(A258,[2]MTP!$A:$AO,41,0) -> 2
A259: SH-DVN-ST | B259: Y | C259: Dolvin Mini Spice Rack | D259: =VLOOKUP(A259,[2]MTP!$A:$B,2,0) -> 1299 | F259: =VLOOKUP(A259,[2]MTP!$A:$E,5,0) -> 299 | G259: =VLOOKUP(A259,[2]MTP!$A:$AO,41,0) -> 3
A260: TU-VC | B260: Y | C260: Victor TV Unit | D260: =VLOOKUP(A260,[2]MTP!$A:$B,2,0) -> 5799 | F260: =VLOOKUP(A260,[2]MTP!$A:$E,5,0) -> 2799 | G260: =VLOOKUP(A260,[2]MTP!$A:$AO,41,0) -> 1
A261: TU-PIN | B261: Y | C261: Pinn TV Unit | D261: =VLOOKUP(A261,[2]MTP!$A:$B,2,0) -> 14999 | F261: =VLOOKUP(A261,[2]MTP!$A:$E,5,0) -> 8999 | G261: =VLOOKUP(A261,[2]MTP!$A:$AO,41,0) -> 3
A262: TU-OLA | B262: Y | C262: Orelia TV Unit | D262: =VLOOKUP(A262,[2]MTP!$A:$B,2,0) -> 9999 | F262: =VLOOKUP(A262,[2]MTP!$A:$E,5,0) -> 5399 | G262: =VLOOKUP(A262,[2]MTP!$A:$AO,41,0) -> 3
A263: TU-AMY | B263: Y | C263: Amy TV Unit | D263: =VLOOKUP(A263,[2]MTP!$A:$B,2,0) -> 10799 | F263: =VLOOKUP(A263,[2]MTP!$A:$E,5,0) -> 6299 | G263: =VLOOKUP(A263,[2]MTP!$A:$AO,41,0) -> 3
A264: TU-HRI | B264: Y | C264: Harri TV Unit | D264: =VLOOKUP(A264,[2]MTP!$A:$B,2,0) -> 8499 | F264: =VLOOKUP(A264,[2]MTP!$A:$E,5,0) -> 5199 | G264: =VLOOKUP(A264,[2]MTP!$A:$AO,41,0) -> 3
A265: TU-LMI | B265: Y | C265: Lami TV Unit | D265: =VLOOKUP(A265,[2]MTP!$A:$B,2,0) -> 9299 | F265: =VLOOKUP(A265,[2]MTP!$A:$E,5,0) -> 5999 | G265: =VLOOKUP(A265,[2]MTP!$A:$AO,41,0) -> 3
... A271: SB-SRA | B271: Y | C271: Senara Bookshelf | D271: =VLOOKUP(A271,[2]MTP!$A:$B,2,0) -> 3999 | F271: =VLOOKUP(A271,[2]MTP!$A:$E,5,0) -> 1499 | G271: =VLOOKUP(A271,[2]MTP!$A:$AO,41,0) -> 6
A272: SB-CA | B272: DI
A273: SB-CS-ST | B273: DI
A274: S-BR-4 | B274: DI
A275: SR-ADS-2W | B275: DI
A276: SR-BKN-M | B276: DI
...

Sheet pIVOT
A2: Chk | B2: Count of ASIN | C2: Count of FK FSN | D2: Count of UL | E2: Count of PF
A3: RL | B3: 9 | C3: 9 | D3: 5 | E3: 9
A4: Y | B4: 227 | C4: 227 | D4: 208 | E4: 225
A5: YB | B5: 7 | C5: 7 | D5: 7 | E5: 7
A6: YD | B6: 3 | C6: 3 | D6: 3 | E6: 3
A7: Grand Total | B7: 246 | C7: 246 | D7: 223 | E7: 244

Sheet Archived Data 
A1: SKU Code | B1: Chk | C1: OSR | D1: MTP SKU | E1: Product Name | F1: FNSKU | G1: ASIN | H1: FK FSN | I1: FK List.ID | J1: UL | K1: PF
A2: SB-AXA-W51-HB | B2: Y | C2: 1 | D2: #N/A | F2: X0012WJNZV | G2: #N/A | H2: #N/A | I2: #N/A | J2: #N/A | K2: #N/A
A3: SB-AXA-W32-HB | B3: Y | C3: 3 | D3: #N/A | F3: X0012VD2IV | G3: #N/A | H3: #N/A | I3: #N/A | J3: #N/A | K3: #N/A
A4: TU-PM-STWDB | B4: Y | C4: 2 | D4: #N/A | F4: X001KLQ39X | G4: #N/A | H4: #N/A | I4: #N/A | J4: FVSGAV33BB20550 | K4: FN1987996-S-PM39235
A5: GEC-007R | B5: Y | C5: 11 | D5: #N/A | F5: X000W9K4XZ | G5: #N/A | H5: #N/A | I5: #N/A | J5: #N/A | K5: #N/A
A6: GEC-L5 | B6: Y | C6: 6 | D6: #N/A | F6: X000MIORE3 | G6: #N/A | H6: #N/A | I6: #N/A | J6: #N/A | K6: #N/A
A7: GEC-004L | B7: Y | C7: 4 | D7: #N/A | F7: X000W9ICG1 | G7: #N/A | H7: #N/A | I7: #N/A | J7: #N/A | K7: #N/A
A8: GEC-L5E | B8: Y | C8: 9 | D8: #N/A | F8: X000TJFDDJ | G8: #N/A | H8: #N/A | I8: #N/A | J8: #N/A | K8: #N/A
A9: GEC-L6M | B9: YD | C9: 19 | D9: #N/A | F9: X000TJZ4AB | G9: #N/A | H9: #N/A | I9: #N/A | J9: #N/A | K9: #N/A
A10: GEC-L4M-SS | B10: Y | C10: 7 | D10: #N/A | F10: X000TK4N7F | G10: #N/A | H10: #N/A | I10: #N/A | J10: #N/A | K10: #N/A
A11: GEC-L6M-SS | B11: NL | C11: 41 | D11: #N/A | F11: X000TK4M5X | G11: #N/A | H11: #N/A | I11: #N/A | J11: #N/A | K11: #N/A
A12: GEC-L7M-SS | B12: Y | C12: 17 | D12: #N/A | F12: X000MG9RDV | G12: #N/A | H12: #N/A | I12: #N/A | J12: #N/A | K12: #N/A
A13: GEC-002XL | B13: y | C13: 10 | D13: #N/A | F13: X000W9KTKX | G13: #N/A | H13: #N/A | I13: #N/A | J13: #N/A | K13: #N/A
A14: BRC-762-WH | B14: y | C14: 12 | D14: #N/A | F14: X000NK059V | G14: #N/A | H14: #N/A | I14: #N/A | J14: #N/A | K14: #N/A
A15: GEC-L4 | B15: NL | C15: 26 | D15: #N/A | F15: X000MDOVJ9 | G15: #N/A | H15: #N/A | I15: #N/A | J15: #N/A | K15: #N/A
A16: GEC-L3M | B16: Y | C16: 5 | D16: #N/A | F16: X000MJKVID | G16: #N/A | H16: #N/A | I16: #N/A | J16: #N/A | K16: #N/A
... A75: AV-MF-01C3 | B75: NL | C75: 125 | D75: #N/A | F75: X000KKFESV | G75: #N/A | H75: #N/A | I75: #N/A | J75: #N/A | K75: #N/A
A76: RT-T1-L | B76: Y | C76: 67 | D76: 0 | F76: X000VZKQBZ | G76: B07CVLRLMR | H76: RSFFC9VEEZHEKD7V | I76: LSTRSFFC9VEEZHEKD7VZWQ9LX | J76: FVSGCB33WL25121 | K76: #N/A
A77: KH-ND-6W | B77: y | C77: 53 | D77: 0 | F77: X000UIS74V | G77: #N/A | H77: KHRF46EGUZ2SN4RJ | I77: LSTKHRF46EGUZ2SN4RJANCNFF | J77: #N/A | K77: #N/A
A78: WVB-SKH-09-6H | B78: Y | C78: 93 | D78: #N/A | F78: X0014454CX | G78: #N/A | H78: #N/A | I78: #N/A | J78: #N/A | K78: #N/A
A79: WVB-EV-RH | B79: Y | C79: 95 | D79: #N/A | F79: X00143VA1D | G79: #N/A | H79: #N/A | I79: #N/A | J79: #N/A | K79: #N/A
A80: WVB-KZ-RH | B80: Y | C80: 87 | D80: #N/A | F80: X00143U2UX | G80: #N/A | H80: #N/A | I80: #N/A | J80: #N/A | K80: #N/A
A81: WVB-MA-RH | B81: NL | C81: 243 | D81: #N/A | F81: X00133D5SZ | G81: #N/A | H81: #N/A | I81: #N/A | J81: #N/A | K81: #N/A
A82: WVB-SG-RH | B82: y | C82: 130 | D82: #N/A | F82: X0012ZPYLF | G82: #N/A | H82: #N/A | I82: #N/A | J82: #N/A | K82: #N/A
A83: WVB-SI-RH | B83: Y | C83: 63 | D83: #N/A | F83: X00135QON1 | G83: #N/A | H83: #N/A | I83: #N/A | J83: #N/A | K83: #N/A
A84: WVB-SL-RH | B84: Y | C84: 44 | D84: #N/A | F84: X0012ZPYZV | G84: #N/A | H84: #N/A | I84: #N/A | J84: #N/A | K84: #N/A
A85: WVB-SR-RH | B85: NL | C85: 128 | D85: #N/A | F85: X00132THF1 | G85: #N/A | H85: #N/A | I85: #N/A | J85: #N/A | K85: #N/A
A86: WVB-SU-RH | B86: Y | C86: 71 | D86: #N/A | F86: X00146P8EP | G86: #N/A | H86: #N/A | I86: #N/A | J86: #N/A | K86: #N/A
A87: WVB-SG-TRA 18 | B87: Y | C87: 137 | D87: #N/A | F87: X00134H4YF | G87: #N/A | H87: #N/A | I87: #N/A | J87: #N/A | K87: #N/A
A88: WVB-SG-TRA-18 | B88: NL | C88: 243 | D88: #N/A | F88: X00144AEKF | G88: #N/A | H88: #N/A | I88: #N/A | J88: #N/A | K88: #N/A
A89: WVB-SR-TRA-18 | B89: Y | C89: 167 | D89: #N/A | F89: X0012ZPZ19 | G89: #N/A | H89: #N/A | I89: #N/A | J89: #N/A | K89: #N/A
... A235: MH-A5S-W | B235: Y | C235: 243 | D235: #N/A | F235: X000KJ2N9F | G235: #N/A | H235: #N/A | I235: #N/A | J235: #N/A | K235: #N/A
A236: PC-AY-LW | B236: Y | C236: 234 | D236: #N/A | F236: X000UEW0PR | G236: B077XDNC3W | H236: #N/A | I236: #N/A | J236: #N/A | K236: #N/A
A237: KH-ND-12W | B237: NL | C237: 239 | D237: #N/A | F237: X000UBV1NH | G237: #N/A | H237: #N/A | I237: #N/A | J237: #N/A | K237: #N/A
A238: PC-SM-LW | B238: y | C238: 230 | D238: #N/A | F238: X000UV31J9 | G238: #N/A | H238: #N/A | I238: #N/A | J238: #N/A | K238: #N/A
A239: MH-WSB-2 | B239: DI | C239: 233 | D239: #N/A | F239: X000KI79V3 | G239: #N/A | H239: #N/A | I239: #N/A | J239: #N/A | K239: #N/A
A240: MH-EB-4 | B240: Y | C240: 221 | D240: #N/A | F240: X000KKFENV | G240: #N/A | H240: #N/A | I240: #N/A | J240: #N/A | K240: #N/A
A241: MH-EW-4 | B241: Y | C241: 204 | D241: #N/A | F241: X000KM4485 | G241: #N/A | H241: #N/A | I241: #N/A | J241: #N/A | K241: #N/A
A242: MH-EA-4 | B242: Y | C242: 235 | D242: #N/A | F242: X000KM2AXL | G242: B00T7O0MGW | H242: #N/A | I242: #N/A | J242: #N/A | K242: #N/A
A243: MH-ER-4 | B243: NL | C243: 223 | D243: #N/A | F243: X000KM4363 | G243: #N/A | H243: #N/A | I243: #N/A | J243: #N/A | K243: #N/A
...
