Workbook

Sheet Billing Dimensions
A1: MANUAL ENTRIES HERE | C1: Box 1 Dimension Details | G1: Box 2 Dimension Details | K1: Box 3 Dimension Details | O1: Volume | P1: Vol.Wht | Q1: Total Weight | S1: Chg.Wht | U1: Check (+ve = Bill wt is less (gain))
C2: Long | D2: Med | E2: Smal | F2: Actual.Wht | G2: Long | H2: Med | I2: Smal | J2: Actual.Wht | K2: Long | L2: Med | M2: Smal | N2: Actual.Wht | O2: CBF | P2: 6 | Q2: Phys.Wht | R2: Wht(Kgs)
A3: MTP SKU Code | B3: SB/MB | C3: Lcm | D3: Bcm | E3: Hcm | F3: PW(gm) | G3: Lcm2 | H3: Bcm3 | I3: Hcm4 | J3: PW(gm)5 | K3: Lcm6 | L3: Bcm7 | M3: Hcm8 | N3: PW(gm)9 | O3: Column15 | P3: Kgs | Q3: Gms | R3: Kgs10 | S3: Column11 | T3: MTP.Chk | U3: B1.Aud | V3: B1.Diff | W3: B1.Diff% | X3: B2.Aud | Y3: B2.Diff | Z3: B2.Diff2% | AA3: B3.Aud | AB3: B3.Diff | AC3: B3.Diff% | AD3: BaLL.Aud | AE3: BAll.Diff%
A4: SB-SRA | B4: SB | C4: =_xlfn.XLOOKUP(Table1[[#This Row],[MTP SKU Code]],'Audit Dimensions'!A:A,'Audit Dimensions'!C:C,0) -> 0 | D4: =_xlfn.XLOOKUP(Table1[[#This Row],[MTP SKU Code]],'Audit Dimensions'!$A:$A,'Audit Dimensions'!D:D,0) -> 0 | E4: =_xlfn.XLOOKUP(Table1[[#This Row],[MTP SKU Code]],'Audit Dimensions'!$A:$A,'Audit Dimensions'!E:E,0) -> 0 | F4: =_xlfn.XLOOKUP(Table1[[#This Row],[MTP SKU Code]],'Audit Dimensions'!$A:$A,'Audit Dimensions'!F:F,0) -> 4800 | G4: =_xlfn.XLOOKUP(Table1[[#This Row],[MTP SKU Code]],'Audit Dimensions'!$A:$A,'Audit Dimensions'!G:G,0) -> 0 | H4: =_xlfn.XLOOKUP(Table1[[#This Row],[MTP SKU Code]],'Audit Dimensions'!$A:$A,'Audit Dimensions'!H:H,0) -> 0 | I4: =_xlfn.XLOOKUP(Table1[[#This Row],[MTP SKU Code]],'Audit Dimensions'!$A:$A,'Audit Dimensions'!I:I,0) -> 0 | J4: =_xlfn.XLOOKUP(Table1[[#This Row],[MTP SKU Code]],'Audit Dimensions'!$A:$A,'Audit Dimensions'!J:J,0) -> 0 | K4: =_xlfn.XLOOKUP(Table1[[#This Row],[MTP SKU Code]],'Audit Dimensions'!$A:$A,'Audit Dimensions'!K:K,0) -> 0 | L4: =_xlfn.XLOOKUP(Table1[[#This Row],[MTP SKU Code]],'Audit Dimensions'!$A:$A,'Audit Dimensions'!L:L,0) -> 0 | M4: =_xlfn.XLOOKUP(Table1[[#This Row],[MTP SKU Code]],'Audit Dimensions'!$A:$A,'Audit Dimensions'!M:M,0) -> 0 | N4: =_xlfn.XLOOKUP(Table1[[#This Row],[MTP SKU Code]],'Audit Dimensions'!$A:$A,'Audit Dimensions'!N:N,0) -> 0 | O4: =((IFERROR((C4*D4*E4),0)+IFERROR((G4*H4*I4),0)+IFERROR((K4*L4*M4),0))/1000000)*35.32 -> 0 | P4: =Table1[[#This Row],[Column15]]*$P$2*1000 -> 0 | Q4: =F4+J4+N4 -> 4800 | R4: =MAX(Q4,O4) -> 4800 | S4: =MAX(R4,P4) -> 4800 | T4: =VLOOKUP(A4,'[1]MTP SKUs - Master Data'!$A:$B,2,FALSE) -> Y | U4: =_xlfn.IFNA(VLOOKUP(Table1[[#This Row],[MTP SKU Code]],'Audit Dimensions'!A:N,6,FALSE),"ARC") -> 4800 | V4: =IFERROR(Table1[[#This Row],[B1.Aud]]-Table1[[#This Row],[PW(gm)]],"ERR") -> 0 | W4: =IFERROR(Table1[[#This Row],[B1.Diff]]/Table1[[#This Row],[B1.Aud]],"ERR") -> 0 | X4: =_xlfn.IFNA(VLOOKUP(Table1[[#This Row],[MTP SKU Code]],'Audit Dimensions'!A:N,10,FALSE),"ARC") -> 0 | Y4: =IFERROR(Table1[[#This Row],[B2.Aud]]-Table1[[#This Row],[PW(gm)5]],"ERR") -> 0 | Z4: =IFERROR(Table1[[#This Row],[B2.Diff]]/Table1[[#This Row],[B2.Aud]],"NA") -> NA | AA4: =_xlfn.IFNA(VLOOKUP(Table1[[#This Row],[MTP SKU Code]],'Audit Dimensions'!A:N,14,FALSE),"ARC") -> 0 | AB4: =IFERROR(Table1[[#This Row],[B3.Aud]]-Table1[[#This Row],[PW(gm)9]],"ERR") -> 0 | AC4: =IFERROR(Table1[[#This Row],[B3.Diff]]/Table1[[#This Row],[BaLL.Aud]],"ERR") -> 0 | AD4: =_xlfn.IFNA(VLOOKUP(Table1[[#This Row],[MTP SKU Code]],'Audit Dimensions'!A:U,16,FALSE),"ARC") -> 4800 | AE4: =IFERROR(1-Table1[[#This Row],[Gms]]/Table1[[#This Row],[BaLL.Aud]],"ERR") -> 0
A5: WA-PYS-N | B5: SB | C5: =_xlfn.XLOOKUP(Table1[[#This Row],[MTP SKU Code]],'Audit Dimensions'!A:A,'Audit Dimensions'!C:C,0) -> 70 | D5: =_xlfn.XLOOKUP(Table1[[#This Row],[MTP SKU Code]],'Audit Dimensions'!$A:$A,'Audit Dimensions'!D:D,0) -> 23 | E5: 5 | F5: 1890 | G5: =_xlfn.XLOOKUP(Table1[[#This Row],[MTP SKU Code]],'Audit Dimensions'!$A:$A,'Audit Dimensions'!G:G,0) -> 0 | H5: =_xlfn.XLOOKUP(Table1[[#This Row],[MTP SKU Code]],'Audit Dimensions'!$A:$A,'Audit Dimensions'!H:H,0) -> 0 | I5: =_xlfn.XLOOKUP(Table1[[#This Row],[MTP SKU Code]],'Audit Dimensions'!$A:$A,'Audit Dimensions'!I:I,0) -> 0 | J5: =_xlfn.XLOOKUP(Table1[[#This Row],[MTP SKU Code]],'Audit Dimensions'!$A:$A,'Audit Dimensions'!J:J,0) -> 0 | K5: =_xlfn.XLOOKUP(Table1[[#This Row],[MTP SKU Code]],'Audit Dimensions'!$A:$A,'Audit Dimensions'!K:K,0) -> 0 | L5: =_xlfn.XLOOKUP(Table1[[#This Row],[MTP SKU Code]],'Audit Dimensions'!$A:$A,'Audit Dimensions'!L:L,0) -> 0 | M5: =_xlfn.XLOOKUP(Table1[[#This Row],[MTP SKU Code]],'Audit Dimensions'!$A:$A,'Audit Dimensions'!M:M,0) -> 0 | N5: =_xlfn.XLOOKUP(Table1[[#This Row],[MTP SKU Code]],'Audit Dimensions'!$A:$A,'Audit Dimensions'!N:N,0) -> 0 | O5: =((IFERROR((C5*D5*E5),0)+IFERROR((G5*H5*I5),0)+IFERROR((K5*L5*M5),0))/1000000)*35.32 -> 0.284326 | P5: =Table1[[#This Row],[Column15]]*$P$2*1000 -> 1705.956 | Q5: =F5+J5+N5 -> 1890 | R5: =MAX(Q5,O5) -> 1890 | S5: =MAX(R5,P5) -> 1890 | T5: =VLOOKUP(A5,'[1]MTP SKUs - Master Data'!$A:$B,2,FALSE) -> Y | U5: =_xlfn.IFNA(VLOOKUP(Table1[[#This Row],[MTP SKU Code]],'Audit Dimensions'!A:N,6,FALSE),"ARC") -> 1940 | V5: =IFERROR(Table1[[#This Row],[B1.Aud]]-Table1[[#This Row],[PW(gm)]],"ERR") -> 50 | W5: =IFERROR(Table1[[#This Row],[B1.Diff]]/Table1[[#This Row],[B1.Aud]],"ERR") -> 0.025773196 | X5: =_xlfn.IFNA(VLOOKUP(Table1[[#This Row],[MTP SKU Code]],'Audit Dimensions'!A:N,10,FALSE),"ARC") -> 0 | Y5: =IFERROR(Table1[[#This Row],[B2.Aud]]-Table1[[#This Row],[PW(gm)5]],"ERR") -> 0 | Z5: =IFERROR(Table1[[#This Row],[B2.Diff]]/Table1[[#This Row],[B2.Aud]],"NA") -> NA | AA5: =_xlfn.IFNA(VLOOKUP(Table1[[#This Row],[MTP SKU Code]],'Audit Dimensions'!A:N,14,FALSE),"ARC") -> 0 | AB5: =IFERROR(Table1[[#This Row],[B3.Aud]]-Table1[[#This Row],[PW(gm)9]],"ERR") -> 0 | AC5: =IFERROR(Table1[[#This Row],[B3.Diff]]/Table1[[#This Row],[BaLL.Aud]],"ERR") -> 0 | AD5: =_xlfn.IFNA(VLOOKUP(Table1[[#This Row],[MTP SKU Code]],'Audit Dimensions'!A:U,16,FALSE),"ARC") -> 1940 | AE5: =IFERROR(1-Table1[[#This Row],[Gms]]/Table1[[#This Row],[BaLL.Aud]],"ERR") -> 0.025773196
A6: SB-SDA | B6: SB | C6: =_xlfn.XLOOKUP(Table1[[#This Row],[MTP SKU Code]],'Audit Dimensions'!A:A,'Audit Dimensions'!C:C,0) -> 0 | D6: =_xlfn.XLOOKUP(Table1[[#This Row],[MTP SKU Code]],'Audit Dimensions'!$A:$A,'Audit Dimensions'!D:D,0) -> 0 | E6: =_xlfn.XLOOKUP(Table1[[#This Row],[MTP SKU Code]],'Audit Dimensions'!$A:$A,'Audit Dimensions'!E:E,0) -> 0 | F6: =_xlfn.XLOOKUP(Table1[[#This Row],[MTP SKU Code]],'Audit Dimensions'!$A:$A,'Audit Dimensions'!F:F,0) -> 8900 | G6: =_xlfn.XLOOKUP(Table1[[#This Row],[MTP SKU Code]],'Audit Dimensions'!$A:$A,'Audit Dimensions'!G:G,0) -> 0 | H6: =_xlfn.XLOOKUP(Table1[[#This Row],[MTP SKU Code]],'Audit Dimensions'!$A:$A,'Audit Dimensions'!H:H,0) -> 0 | I6: =_xlfn.XLOOKUP(Table1[[#This Row],[MTP SKU Code]],'Audit Dimensions'!$A:$A,'Audit Dimensions'!I:I,0) -> 0 | J6: =_xlfn.XLOOKUP(Table1[[#This Row],[MTP SKU Code]],'Audit Dimensions'!$A:$A,'Audit Dimensions'!J:J,0) -> 0 | K6: =_xlfn.XLOOKUP(Table1[[#This Row],[MTP SKU Code]],'Audit Dimensions'!$A:$A,'Audit Dimensions'!K:K,0) -> 0 | L6: =_xlfn.XLOOKUP(Table1[[#This Row],[MTP SKU Code]],'Audit Dimensions'!$A:$A,'Audit Dimensions'!L:L,0) -> 0 | M6: =_xlfn.XLOOKUP(Table1[[#This Row],[MTP SKU Code]],'Audit Dimensions'!$A:$A,'Audit Dimensions'!M:M,0) -> 0 | N6: =_xlfn.XLOOKUP(Table1[[#This Row],[MTP SKU Code]],'Audit Dimensions'!$A:$A,'Audit Dimensions'!N:N,0) -> 0 | O6: =((IFERROR((C6*D6*E6),0)+IFERROR((G6*H6*I6),0)+IFERROR((K6*L6*M6),0))/1000000)*35.32 -> 0 | P6: =Table1[[#This Row],[Column15]]*$P$2*1000 -> 0 | Q6: =F6+J6+N6 -> 8900 | R6: =MAX(Q6,O6) -> 8900 | S6: =MAX(R6,P6) -> 8900 | T6: =VLOOKUP(A6,'[1]MTP SKUs - Master Data'!$A:$B,2,FALSE) -> Y | U6: =_xlfn.IFNA(VLOOKUP(Table1[[#This Row],[MTP SKU Code]],'Audit Dimensions'!A:N,6,FALSE),"ARC") -> 8900 | V6: =IFERROR(Table1[[#This Row],[B1.Aud]]-Table1[[#This Row],[PW(gm)]],"ERR") -> 0 | W6: =IFERROR(Table1[[#This Row],[B1.Diff]]/Table1[[#This Row],[B1.Aud]],"ERR") -> 0 | X6: =_xlfn.IFNA(VLOOKUP(Table1[[#This Row],[MTP SKU Code]],'Audit Dimensions'!A:N,10,FALSE),"ARC") -> 0 | Y6: =IFERROR(Table1[[#This Row],[B2.Aud]]-Table1[[#This Row],[PW(gm)5]],"ERR") -> 0 | Z6: =IFERROR(Table1[[#This Row],[B2.Diff]]/Table1[[#This Row],[B2.Aud]],"NA") -> NA | AA6: =_xlfn.IFNA(VLOOKUP(Table1[[#This Row],[MTP SKU Code]],'Audit Dimensions'!A:N,14,FALSE),"ARC") -> 0 | AB6: =IFERROR(Table1[[#This Row],[B3.Aud]]-Table1[[#This Row],[PW(gm)9]],"ERR") -> 0 | AC6: =IFERROR(Table1[[#This Row],[B3.Diff]]/Table1[[#This Row],[BaLL.Aud]],"ERR") -> 0 | AD6: =_xlfn.IFNA(VLOOKUP(Table1[[#This Row],[MTP SKU Code]],'Audit Dimensions'!A:U,16,FALSE),"ARC") -> 8900 | AE6: =IFERROR(1-Table1[[#This Row],[Gms]]/Table1[[#This Row],[BaLL.Aud]],"ERR") -> 0
A7: SB-OVO | B7: SB | C7: =_xlfn.XLOOKUP(Table1[[#This Row],[MTP SKU Code]],'Audit Dimensions'!A:A,'Audit Dimensions'!C:C,0) -> 0 | D7: =_xlfn.XLOOKUP(Table1[[#This Row],[MTP SKU Code]],'Audit Dimensions'!$A:$A,'Audit Dimensions'!D:D,0) -> 0 | E7: =_xlfn.XLOOKUP(Table1[[#This Row],[MTP SKU Code]],'Audit Dimensions'!$A:$A,'Audit Dimensions'!E:E,0) -> 0 | F7: 30500 | G7: =_xlfn.XLOOKUP(Table1[[#This Row],[MTP SKU Code]],'Audit Dimensions'!$A:$A,'Audit Dimensions'!G:G,0) -> 0 | H7: =_xlfn.XLOOKUP(Table1[[#This Row],[MTP SKU Code]],'Audit Dimensions'!$A:$A,'Audit Dimensions'!H:H,0) -> 0 | I7: =_xlfn.XLOOKUP(Table1[[#This Row],[MTP SKU Code]],'Audit Dimensions'!$A:$A,'Audit Dimensions'!I:I,0) -> 0 | J7: =_xlfn.XLOOKUP(Table1[[#This Row],[MTP SKU Code]],'Audit Dimensions'!$A:$A,'Audit Dimensions'!J:J,0) -> 0 | K7: =_xlfn.XLOOKUP(Table1[[#This Row],[MTP SKU Code]],'Audit Dimensions'!$A:$A,'Audit Dimensions'!K:K,0) -> 0 | L7: =_xlfn.XLOOKUP(Table1[[#This Row],[MTP SKU Code]],'Audit Dimensions'!$A:$A,'Audit Dimensions'!L:L,0) -> 0 | M7: =_xlfn.XLOOKUP(Table1[[#This Row],[MTP SKU Code]],'Audit Dimensions'!$A:$A,'Audit Dimensions'!M:M,0) -> 0 | N7: =_xlfn.XLOOKUP(Table1[[#This Row],[MTP SKU Code]],'Audit Dimensions'!$A:$A,'Audit Dimensions'!N:N,0) -> 0 | O7: =((IFERROR((C7*D7*E7),0)+IFERROR((G7*H7*I7),0)+IFERROR((K7*L7*M7),0))/1000000)*35.32 -> 0 | P7: =Table1[[#This Row],[Column15]]*$P$2*1000 -> 0 | Q7: =F7+J7+N7 -> 30500 | R7: =MAX(Q7,O7) -> 30500 | S7: =MAX(R7,P7) -> 30500 | T7: =VLOOKUP(A7,'[1]MTP SKUs - Master Data'!$A:$B,2,FALSE) -> Y | U7: =_xlfn.IFNA(VLOOKUP(Table1[[#This Row],[MTP SKU Code]],'Audit Dimensions'!A:N,6,FALSE),"ARC") -> 31800 | V7: =IFERROR(Table1[[#This Row],[B1.Aud]]-Table1[[#This Row],[PW(gm)]],"ERR") -> 1300 | W7: =IFERROR(Table1[[#This Row],[B1.Diff]]/Table1[[#This Row],[B1.Aud]],"ERR") -> 0.040880503 | X7: =_xlfn.IFNA(VLOOKUP(Table1[[#This Row],[MTP SKU Code]],'Audit Dimensions'!A:N,10,FALSE),"ARC") -> 0 | Y7: =IFERROR(Table1[[#This Row],[B2.Aud]]-Table1[[#This Row],[PW(gm)5]],"ERR") -> 0 | Z7: =IFERROR(Table1[[#This Row],[B2.Diff]]/Table1[[#This Row],[B2.Aud]],"NA") -> NA | AA7: =_xlfn.IFNA(VLOOKUP(Table1[[#This Row],[MTP SKU Code]],'Audit Dimensions'!A:N,14,FALSE),"ARC") -> 0 | AB7: =IFERROR(Table1[[#This Row],[B3.Aud]]-Table1[[#This Row],[PW(gm)9]],"ERR") -> 0 | AC7: =IFERROR(Table1[[#This Row],[B3.Diff]]/Table1[[#This Row],[BaLL.Aud]],"ERR") -> 0 | AD7: =_xlfn.IFNA(VLOOKUP(Table1[[#This Row],[MTP SKU Code]],'Audit Dimensions'!A:U,16,FALSE),"ARC") -> 31800 | AE7: =IFERROR(1-Table1[[#This Row],[Gms]]/Table1[[#This Row],[BaLL.Aud]],"ERR") -> 0.040880503
A8: KH-SUT-21 | B8: SB | C8: 32 | D8: 30 | E8: 4 | F8: =_xlfn.XLOOKUP(Table1[[#This Row],[MTP SKU Code]],'Audit Dimensions'!$A:$A,'Audit Dimensions'!F:F,0) -> 750 | G8: =_xlfn.XLOOKUP(Table1[[#This Row],[MTP SKU Code]],'Audit Dimensions'!$A:$A,'Audit Dimensions'!G:G,0) -> 0 | H8: =_xlfn.XLOOKUP(Table1[[#This Row],[MTP SKU Code]],'Audit Dimensions'!$A:$A,'Audit Dimensions'!H:H,0) -> 0 | I8: =_xlfn.XLOOKUP(Table1[[#This Row],[MTP SKU Code]],'Audit Dimensions'!$A:$A,'Audit Dimensions'!I:I,0) -> 0 | J8: =_xlfn.XLOOKUP(Table1[[#This Row],[MTP SKU Code]],'Audit Dimensions'!$A:$A,'Audit Dimensions'!J:J,0) -> 0 | K8: =_xlfn.XLOOKUP(Table1[[#This Row],[MTP SKU Code]],'Audit Dimensions'!$A:$A,'Audit Dimensions'!K:K,0) -> 0 | L8: =_xlfn.XLOOKUP(Table1[[#This Row],[MTP SKU Code]],'Audit Dimensions'!$A:$A,'Audit Dimensions'!L:L,0) -> 0 | M8: =_xlfn.XLOOKUP(Table1[[#This Row],[MTP SKU Code]],'Audit Dimensions'!$A:$A,'Audit Dimensions'!M:M,0) -> 0 | N8: =_xlfn.XLOOKUP(Table1[[#This Row],[MTP SKU Code]],'Audit Dimensions'!$A:$A,'Audit Dimensions'!N:N,0) -> 0 | O8: =((IFERROR((C8*D8*E8),0)+IFERROR((G8*H8*I8),0)+IFERROR((K8*L8*M8),0))/1000000)*35.32 -> 0.1356288 | P8: =Table1[[#This Row],[Column15]]*$P$2*1000 -> 813.7728 | Q8: =F8+J8+N8 -> 750 | R8: =MAX(Q8,O8) -> 750 | S8: =MAX(R8,P8) -> 813.7728 | T8: =VLOOKUP(A8,'[1]MTP SKUs - Master Data'!$A:$B,2,FALSE) -> Y | U8: =_xlfn.IFNA(VLOOKUP(Table1[[#This Row],[MTP SKU Code]],'Audit Dimensions'!A:N,6,FALSE),"ARC") -> 750 | V8: =IFERROR(Table1[[#This Row],[B1.Aud]]-Table1[[#This Row],[PW(gm)]],"ERR") -> 0 | W8: =IFERROR(Table1[[#This Row],[B1.Diff]]/Table1[[#This Row],[B1.Aud]],"ERR") -> 0 | X8: =_xlfn.IFNA(VLOOKUP(Table1[[#This Row],[MTP SKU Code]],'Audit Dimensions'!A:N,10,FALSE),"ARC") -> 0 | Y8: =IFERROR(Table1[[#This Row],[B2.Aud]]-Table1[[#This Row],[PW(gm)5]],"ERR") -> 0 | Z8: =IFERROR(Table1[[#This Row],[B2.Diff]]/Table1[[#This Row],[B2.Aud]],"NA") -> NA | AA8: =_xlfn.IFNA(VLOOKUP(Table1[[#This Row],[MTP SKU Code]],'Audit Dimensions'!A:N,14,FALSE),"ARC") -> 0 | AB8: =IFERROR(Table1[[#This Row],[B3.Aud]]-Table1[[#This Row],[PW(gm)9]],"ERR") -> 0 | AC8: =IFERROR(Table1[[#This Row],[B3.Diff]]/Table1[[#This Row],[BaLL.Aud]],"ERR") -> 0 | AD8: =_xlfn.IFNA(VLOOKUP(Table1[[#This Row],[MTP SKU Code]],'Audit Dimensions'!A:U,16,FALSE),"ARC") -> 750 | AE8: =IFERROR(1-Table1[[#This Row],[Gms]]/Table1[[#This Row],[BaLL.Aud]],"ERR") -> 0
A9: KH-SUT-5 | B9: SB | C9: 35 | D9: 10 | E9: 5 | F9: =_xlfn.XLOOKUP(Table1[[#This Row],[MTP SKU Code]],'Audit Dimensions'!$A:$A,'Audit Dimensions'!F:F,0) -> 202 | G9: =_xlfn.XLOOKUP(Table1[[#This Row],[MTP SKU Code]],'Audit Dimensions'!$A:$A,'Audit Dimensions'!G:G,0) -> 0 | H9: =_xlfn.XLOOKUP(Table1[[#This Row],[MTP SKU Code]],'Audit Dimensions'!$A:$A,'Audit Dimensions'!H:H,0) -> 0 | I9: =_xlfn.XLOOKUP(Table1[[#This Row],[MTP SKU Code]],'Audit Dimensions'!$A:$A,'Audit Dimensions'!I:I,0) -> 0 | J9: =_xlfn.XLOOKUP(Table1[[#This Row],[MTP SKU Code]],'Audit Dimensions'!$A:$A,'Audit Dimensions'!J:J,0) -> 0 | K9: =_xlfn.XLOOKUP(Table1[[#This Row],[MTP SKU Code]],'Audit Dimensions'!$A:$A,'Audit Dimensions'!K:K,0) -> 0 | L9: =_xlfn.XLOOKUP(Table1[[#This Row],[MTP SKU Code]],'Audit Dimensions'!$A:$A,'Audit Dimensions'!L:L,0) -> 0 | M9: =_xlfn.XLOOKUP(Table1[[#This Row],[MTP SKU Code]],'Audit Dimensions'!$A:$A,'Audit Dimensions'!M:M,0) -> 0 | N9: =_xlfn.XLOOKUP(Table1[[#This Row],[MTP SKU Code]],'Audit Dimensions'!$A:$A,'Audit Dimensions'!N:N,0) -> 0 | O9: =((IFERROR((C9*D9*E9),0)+IFERROR((G9*H9*I9),0)+IFERROR((K9*L9*M9),0))/1000000)*35.32 -> 0.06181 | P9: =Table1[[#This Row],[Column15]]*$P$2*1000 -> 370.86 | Q9: =F9+J9+N9 -> 202 | R9: =MAX(Q9,O9) -> 202 | S9: =MAX(R9,P9) -> 370.86 | T9: =VLOOKUP(A9,'[1]MTP SKUs - Master Data'!$A:$B,2,FALSE) -> Y | U9: =_xlfn.IFNA(VLOOKUP(Table1[[#This Row],[MTP SKU Code]],'Audit Dimensions'!A:N,6,FALSE),"ARC") -> 202 | V9: =IFERROR(Table1[[#This Row],[B1.Aud]]-Table1[[#This Row],[PW(gm)]],"ERR") -> 0 | W9: =IFERROR(Table1[[#This Row],[B1.Diff]]/Table1[[#This Row],[B1.Aud]],"ERR") -> 0 | X9: =_xlfn.IFNA(VLOOKUP(Table1[[#This Row],[MTP SKU Code]],'Audit Dimensions'!A:N,10,FALSE),"ARC") -> 0 | Y9: =IFERROR(Table1[[#This Row],[B2.Aud]]-Table1[[#This Row],[PW(gm)5]],"ERR") -> 0 | Z9: =IFERROR(Table1[[#This Row],[B2.Diff]]/Table1[[#This Row],[B2.Aud]],"NA") -> NA | AA9: =_xlfn.IFNA(VLOOKUP(Table1[[#This Row],[MTP SKU Code]],'Audit Dimensions'!A:N,14,FALSE),"ARC") -> 0 | AB9: =IFERROR(Table1[[#This Row],[B3.Aud]]-Table1[[#This Row],[PW(gm)9]],"ERR") -> 0 | AC9: =IFERROR(Table1[[#This Row],[B3.Diff]]/Table1[[#This Row],[BaLL.Aud]],"ERR") -> 0 | AD9: =_xlfn.IFNA(VLOOKUP(Table1[[#This Row],[MTP SKU Code]],'Audit Dimensions'!A:U,16,FALSE),"ARC") -> 202 | AE9: =IFERROR(1-Table1[[#This Row],[Gms]]/Table1[[#This Row],[BaLL.Aud]],"ERR") -> 0
A10: KH-WLR | B10: SB | C10: =_xlfn.XLOOKUP(Table1[[#This Row],[MTP SKU Code]],'Audit Dimensions'!A:A,'Audit Dimensions'!C:C,0) -> 35 | D10: =_xlfn.XLOOKUP(Table1[[#This Row],[MTP SKU Code]],'Audit Dimensions'!$A:$A,'Audit Dimensions'!D:D,0) -> 12 | E10: =_xlfn.XLOOKUP(Table1[[#This Row],[MTP SKU Code]],'Audit Dimensions'!$A:$A,'Audit Dimensions'!E:E,0) -> 4 | F10: =_xlfn.XLOOKUP(Table1[[#This Row],[MTP SKU Code]],'Audit Dimensions'!$A:$A,'Audit Dimensions'!F:F,0) -> 266 | G10: =_xlfn.XLOOKUP(Table1[[#This Row],[MTP SKU Code]],'Audit Dimensions'!$A:$A,'Audit Dimensions'!G:G,0) -> 0 | H10: =_xlfn.XLOOKUP(Table1[[#This Row],[MTP SKU Code]],'Audit Dimensions'!$A:$A,'Audit Dimensions'!H:H,0) -> 0 | I10: =_xlfn.XLOOKUP(Table1[[#This Row],[MTP SKU Code]],'Audit Dimensions'!$A:$A,'Audit Dimensions'!I:I,0) -> 0 | J10: =_xlfn.XLOOKUP(Table1[[#This Row],[MTP SKU Code]],'Audit Dimensions'!$A:$A,'Audit Dimensions'!J:J,0) -> 0 | K10: =_xlfn.XLOOKUP(Table1[[#This Row],[MTP SKU Code]],'Audit Dimensions'!$A:$A,'Audit Dimensions'!K:K,0) -> 0 | L10: =_xlfn.XLOOKUP(Table1[[#This Row],[MTP SKU Code]],'Audit Dimensions'!$A:$A,'Audit Dimensions'!L:L,0) -> 0 | M10: =_xlfn.XLOOKUP(Table1[[#This Row],[MTP SKU Code]],'Audit Dimensions'!$A:$A,'Audit Dimensions'!M:M,0) -> 0 | N10: =_xlfn.XLOOKUP(Table1[[#This Row],[MTP SKU Code]],'Audit Dimensions'!$A:$A,'Audit Dimensions'!N:N,0) -> 0 | O10: =((IFERROR((C10*D10*E10),0)+IFERROR((G10*H10*I10),0)+IFERROR((K10*L10*M10),0))/1000000)*35.32 -> 0.0593376 | P10: =Table1[[#This Row],[Column15]]*$P$2*1000 -> 356.0256 | Q10: =F10+J10+N10 -> 266 | R10: =MAX(Q10,O10) -> 266 | S10: =MAX(R10,P10) -> 356.0256 | T10: =VLOOKUP(A10,'[1]MTP SKUs - Master Data'!$A:$B,2,FALSE) -> RL | U10: =_xlfn.IFNA(VLOOKUP(Table1[[#This Row],[MTP SKU Code]],'Audit Dimensions'!A:N,6,FALSE),"ARC") -> 266 | V10: =IFERROR(Table1[[#This Row],[B1.Aud]]-Table1[[#This Row],[PW(gm)]],"ERR") -> 0 | W10: =IFERROR(Table1[[#This Row],[B1.Diff]]/Table1[[#This Row],[B1.Aud]],"ERR") -> 0 | X10: =_xlfn.IFNA(VLOOKUP(Table1[[#This Row],[MTP SKU Code]],'Audit Dimensions'!A:N,10,FALSE),"ARC") -> 0 | Y10: =IFERROR(Table1[[#This Row],[B2.Aud]]-Table1[[#This Row],[PW(gm)5]],"ERR") -> 0 | Z10: =IFERROR(Table1[[#This Row],[B2.Diff]]/Table1[[#This Row],[B2.Aud]],"NA") -> NA | AA10: =_xlfn.IFNA(VLOOKUP(Table1[[#This Row],[MTP SKU Code]],'Audit Dimensions'!A:N,14,FALSE),"ARC") -> 0 | AB10: =IFERROR(Table1[[#This Row],[B3.Aud]]-Table1[[#This Row],[PW(gm)9]],"ERR") -> 0 | AC10: =IFERROR(Table1[[#This Row],[B3.Diff]]/Table1[[#This Row],[BaLL.Aud]],"ERR") -> 0 | AD10: =_xlfn.IFNA(VLOOKUP(Table1[[#This Row],[MTP SKU Code]],'Audit Dimensions'!A:U,16,FALSE),"ARC") -> 266 | AE10: =IFERROR(1-Table1[[#This Row],[Gms]]/Table1[[#This Row],[BaLL.Aud]],"ERR") -> 0
A11: KH-RMT | B11: SB | C11: 24 | D11: 24 | E11: =_xlfn.XLOOKUP(Table1[[#This Row],[MTP SKU Code]],'Audit Dimensions'!$A:$A,'Audit Dimensions'!E:E,0) -> 3 | F11: =_xlfn.XLOOKUP(Table1[[#This Row],[MTP SKU Code]],'Audit Dimensions'!$A:$A,'Audit Dimensions'!F:F,0) -> 340 | G11: =_xlfn.XLOOKUP(Table1[[#This Row],[MTP SKU Code]],'Audit Dimensions'!$A:$A,'Audit Dimensions'!G:G,0) -> 0 | H11: =_xlfn.XLOOKUP(Table1[[#This Row],[MTP SKU Code]],'Audit Dimensions'!$A:$A,'Audit Dimensions'!H:H,0) -> 0 | I11: =_xlfn.XLOOKUP(Table1[[#This Row],[MTP SKU Code]],'Audit Dimensions'!$A:$A,'Audit Dimensions'!I:I,0) -> 0 | J11: =_xlfn.XLOOKUP(Table1[[#This Row],[MTP SKU Code]],'Audit Dimensions'!$A:$A,'Audit Dimensions'!J:J,0) -> 0 | K11: =_xlfn.XLOOKUP(Table1[[#This Row],[MTP SKU Code]],'Audit Dimensions'!$A:$A,'Audit Dimensions'!K:K,0) -> 0 | L11: =_xlfn.XLOOKUP(Table1[[#This Row],[MTP SKU Code]],'Audit Dimensions'!$A:$A,'Audit Dimensions'!L:L,0) -> 0 | M11: =_xlfn.XLOOKUP(Table1[[#This Row],[MTP SKU Code]],'Audit Dimensions'!$A:$A,'Audit Dimensions'!M:M,0) -> 0 | N11: =_xlfn.XLOOKUP(Table1[[#This Row],[MTP SKU Code]],'Audit Dimensions'!$A:$A,'Audit Dimensions'!N:N,0) -> 0 | O11: =((IFERROR((C11*D11*E11),0)+IFERROR((G11*H11*I11),0)+IFERROR((K11*L11*M11),0))/1000000)*35.32 -> 0.06103296 | P11: =Table1[[#This Row],[Column15]]*$P$2*1000 -> 366.19776 | Q11: =F11+J11+N11 -> 340 | R11: =MAX(Q11,O11) -> 340 | S11: =MAX(R11,P11) -> 366.19776 | T11: =VLOOKUP(A11,'[1]MTP SKUs - Master Data'!$A:$B,2,FALSE) -> Y | U11: =_xlfn.IFNA(VLOOKUP(Table1[[#This Row],[MTP SKU Code]],'Audit Dimensions'!A:N,6,FALSE),"ARC") -> 340 | V11: =IFERROR(Table1[[#This Row],[B1.Aud]]-Table1[[#This Row],[PW(gm)]],"ERR") -> 0 | W11: =IFERROR(Table1[[#This Row],[B1.Diff]]/Table1[[#This Row],[B1.Aud]],"ERR") -> 0 | X11: =_xlfn.IFNA(VLOOKUP(Table1[[#This Row],[MTP SKU Code]],'Audit Dimensions'!A:N,10,FALSE),"ARC") -> 0 | Y11: =IFERROR(Table1[[#This Row],[B2.Aud]]-Table1[[#This Row],[PW(gm)5]],"ERR") -> 0 | Z11: =IFERROR(Table1[[#This Row],[B2.Diff]]/Table1[[#This Row],[B2.Aud]],"NA") -> NA | AA11: =_xlfn.IFNA(VLOOKUP(Table1[[#This Row],[MTP SKU Code]],'Audit Dimensions'!A:N,14,FALSE),"ARC") -> 0 | AB11: =IFERROR(Table1[[#This Row],[B3.Aud]]-Table1[[#This Row],[PW(gm)9]],"ERR") -> 0 | AC11: =IFERROR(Table1[[#This Row],[B3.Diff]]/Table1[[#This Row],[BaLL.Aud]],"ERR") -> 0 | AD11: =_xlfn.IFNA(VLOOKUP(Table1[[#This Row],[MTP SKU Code]],'Audit Dimensions'!A:U,16,FALSE),"ARC") -> 340 | AE11: =IFERROR(1-Table1[[#This Row],[Gms]]/Table1[[#This Row],[BaLL.Aud]],"ERR") -> 0
A12: KH-SW-W10 | B12: SB | C12: =_xlfn.XLOOKUP(Table1[[#This Row],[MTP SKU Code]],'Audit Dimensions'!A:A,'Audit Dimensions'!C:C,0) -> 25 | D12: =_xlfn.XLOOKUP(Table1[[#This Row],[MTP SKU Code]],'Audit Dimensions'!$A:$A,'Audit Dimensions'!D:D,0) -> 25 | E12: =_xlfn.XLOOKUP(Table1[[#This Row],[MTP SKU Code]],'Audit Dimensions'!$A:$A,'Audit Dimensions'!E:E,0) -> 5 | F12: =_xlfn.XLOOKUP(Table1[[#This Row],[MTP SKU Code]],'Audit Dimensions'!$A:$A,'Audit Dimensions'!F:F,0) -> 660 | G12: =_xlfn.XLOOKUP(Table1[[#This Row],[MTP SKU Code]],'Audit Dimensions'!$A:$A,'Audit Dimensions'!G:G,0) -> 0 | H12: =_xlfn.XLOOKUP(Table1[[#This Row],[MTP SKU Code]],'Audit Dimensions'!$A:$A,'Audit Dimensions'!H:H,0) -> 0 | I12: =_xlfn.XLOOKUP(Table1[[#This Row],[MTP SKU Code]],'Audit Dimensions'!$A:$A,'Audit Dimensions'!I:I,0) -> 0 | J12: =_xlfn.XLOOKUP(Table1[[#This Row],[MTP SKU Code]],'Audit Dimensions'!$A:$A,'Audit Dimensions'!J:J,0) -> 0 | K12: =_xlfn.XLOOKUP(Table1[[#This Row],[MTP SKU Code]],'Audit Dimensions'!$A:$A,'Audit Dimensions'!K:K,0) -> 0 | L12: =_xlfn.XLOOKUP(Table1[[#This Row],[MTP SKU Code]],'Audit Dimensions'!$A:$A,'Audit Dimensions'!L:L,0) -> 0 | M12: =_xlfn.XLOOKUP(Table1[[#This Row],[MTP SKU Code]],'Audit Dimensions'!$A:$A,'Audit Dimensions'!M:M,0) -> 0 | N12: =_xlfn.XLOOKUP(Table1[[#This Row],[MTP SKU Code]],'Audit Dimensions'!$A:$A,'Audit Dimensions'!N:N,0) -> 0 | O12: =((IFERROR((C12*D12*E12),0)+IFERROR((G12*H12*I12),0)+IFERROR((K12*L12*M12),0))/1000000)*35.32 -> 0.110375 | P12: =Table1[[#This Row],[Column15]]*$P$2*1000 -> 662.25 | Q12: =F12+J12+N12 -> 660 | R12: =MAX(Q12,O12) -> 660 | S12: =MAX(R12,P12) -> 662.25 | T12: =VLOOKUP(A12,'[1]MTP SKUs - Master Data'!$A:$B,2,FALSE) -> Y | U12: =_xlfn.IFNA(VLOOKUP(Table1[[#This Row],[MTP SKU Code]],'Audit Dimensions'!A:N,6,FALSE),"ARC") -> 660 | V12: =IFERROR(Table1[[#This Row],[B1.Aud]]-Table1[[#This Row],[PW(gm)]],"ERR") -> 0 | W12: =IFERROR(Table1[[#This Row],[B1.Diff]]/Table1[[#This Row],[B1.Aud]],"ERR") -> 0 | X12: =_xlfn.IFNA(VLOOKUP(Table1[[#This Row],[MTP SKU Code]],'Audit Dimensions'!A:N,10,FALSE),"ARC") -> 0 | Y12: =IFERROR(Table1[[#This Row],[B2.Aud]]-Table1[[#This Row],[PW(gm)5]],"ERR") -> 0 | Z12: =IFERROR(Table1[[#This Row],[B2.Diff]]/Table1[[#This Row],[B2.Aud]],"NA") -> NA | AA12: =_xlfn.IFNA(VLOOKUP(Table1[[#This Row],[MTP SKU Code]],'Audit Dimensions'!A:N,14,FALSE),"ARC") -> 0 | AB12: =IFERROR(Table1[[#This Row],[B3.Aud]]-Table1[[#This Row],[PW(gm)9]],"ERR") -> 0 | AC12: =IFERROR(Table1[[#This Row],[B3.Diff]]/Table1[[#This Row],[BaLL.Aud]],"ERR") -> 0 | AD12: =_xlfn.IFNA(VLOOKUP(Table1[[#This Row],[MTP SKU Code]],'Audit Dimensions'!A:U,16,FALSE),"ARC") -> 660 | AE12: =IFERROR(1-Table1[[#This Row],[Gms]]/Table1[[#This Row],[BaLL.Aud]],"ERR") -> 0
A13: KHS-SW-W1 | B13: SB | C13: =_xlfn.XLOOKUP(Table1[[#This Row],[MTP SKU Code]],'Audit Dimensions'!A:A,'Audit Dimensions'!C:C,0) -> 27 | D13: =_xlfn.XLOOKUP(Table1[[#This Row],[MTP SKU Code]],'Audit Dimensions'!$A:$A,'Audit Dimensions'!D:D,0) -> 20 | E13: =_xlfn.XLOOKUP(Table1[[#This Row],[MTP SKU Code]],'Audit Dimensions'!$A:$A,'Audit Dimensions'!E:E,0) -> 6 | F13: =_xlfn.XLOOKUP(Table1[[#This Row],[MTP SKU Code]],'Audit Dimensions'!$A:$A,'Audit Dimensions'!F:F,0) -> 810 | G13: =_xlfn.XLOOKUP(Table1[[#This Row],[MTP SKU Code]],'Audit Dimensions'!$A:$A,'Audit Dimensions'!G:G,0) -> 0 | H13: =_xlfn.XLOOKUP(Table1[[#This Row],[MTP SKU Code]],'Audit Dimensions'!$A:$A,'Audit Dimensions'!H:H,0) -> 0 | I13: =_xlfn.XLOOKUP(Table1[[#This Row],[MTP SKU Code]],'Audit Dimensions'!$A:$A,'Audit Dimensions'!I:I,0) -> 0 | J13: =_xlfn.XLOOKUP(Table1[[#This Row],[MTP SKU Code]],'Audit Dimensions'!$A:$A,'Audit Dimensions'!J:J,0) -> 0 | K13: =_xlfn.XLOOKUP(Table1[[#This Row],[MTP SKU Code]],'Audit Dimensions'!$A:$A,'Audit Dimensions'!K:K,0) -> 0 | L13: =_xlfn.XLOOKUP(Table1[[#This Row],[MTP SKU Code]],'Audit Dimensions'!$A:$A,'Audit Dimensions'!L:L,0) -> 0 | M13: =_xlfn.XLOOKUP(Table1[[#This Row],[MTP SKU Code]],'Audit Dimensions'!$A:$A,'Audit Dimensions'!M:M,0) -> 0 | N13: =_xlfn.XLOOKUP(Table1[[#This Row],[MTP SKU Code]],'Audit Dimensions'!$A:$A,'Audit Dimensions'!N:N,0) -> 0 | O13: =((IFERROR((C13*D13*E13),0)+IFERROR((G13*H13*I13),0)+IFERROR((K13*L13*M13),0))/1000000)*35.32 -> 0.1144368 | P13: =Table1[[#This Row],[Column15]]*$P$2*1000 -> 686.6208 | Q13: =F13+J13+N13 -> 810 | R13: =MAX(Q13,O13) -> 810 | S13: =MAX(R13,P13) -> 810 | T13: =VLOOKUP(A13,'[1]MTP SKUs - Master Data'!$A:$B,2,FALSE) -> Y | U13: =_xlfn.IFNA(VLOOKUP(Table1[[#This Row],[MTP SKU Code]],'Audit Dimensions'!A:N,6,FALSE),"ARC") -> 810 | V13: =IFERROR(Table1[[#This Row],[B1.Aud]]-Table1[[#This Row],[PW(gm)]],"ERR") -> 0 | W13: =IFERROR(Table1[[#This Row],[B1.Diff]]/Table1[[#This Row],[B1.Aud]],"ERR") -> 0 | X13: =_xlfn.IFNA(VLOOKUP(Table1[[#This Row],[MTP SKU Code]],'Audit Dimensions'!A:N,10,FALSE),"ARC") -> 0 | Y13: =IFERROR(Table1[[#This Row],[B2.Aud]]-Table1[[#This Row],[PW(gm)5]],"ERR") -> 0 | Z13: =IFERROR(Table1[[#This Row],[B2.Diff]]/Table1[[#This Row],[B2.Aud]],"NA") -> NA | AA13: =_xlfn.IFNA(VLOOKUP(Table1[[#This Row],[MTP SKU Code]],'Audit Dimensions'!A:N,14,FALSE),"ARC") -> 0 | AB13: =IFERROR(Table1[[#This Row],[B3.Aud]]-Table1[[#This Row],[PW(gm)9]],"ERR") -> 0 | AC13: =IFERROR(Table1[[#This Row],[B3.Diff]]/Table1[[#This Row],[BaLL.Aud]],"ERR") -> 0 | AD13: =_xlfn.IFNA(VLOOKUP(Table1[[#This Row],[MTP SKU Code]],'Audit Dimensions'!A:U,16,FALSE),"ARC") -> 810 | AE13: =IFERROR(1-Table1[[#This Row],[Gms]]/Table1[[#This Row],[BaLL.Aud]],"ERR") -> 0
A14: CT-ATD-ST | B14: SB | C14: 112 | D14: 51 | E14: 5 | F14: 14800 | O14: =((IFERROR((C14*D14*E14),0)+IFERROR((G14*H14*I14),0)+IFERROR((K14*L14*M14),0))/1000000)*35.32 -> 1.0087392 | P14: =Table1[[#This Row],[Column15]]*$P$2*1000 -> 6052.4352 | Q14: =F14+J14+N14 -> 14800 | R14: =MAX(Q14,O14) -> 14800 | S14: =MAX(R14,P14) -> 14800 | T14: =VLOOKUP(A14,'[1]MTP SKUs - Master Data'!$A:$B,2,FALSE) -> DI | U14: =_xlfn.IFNA(VLOOKUP(Table1[[#This Row],[MTP SKU Code]],'Audit Dimensions'!A:N,6,FALSE),"ARC") -> 11250 | V14: =IFERROR(Table1[[#This Row],[B1.Aud]]-Table1[[#This Row],[PW(gm)]],"ERR") -> -3550 | W14: =IFERROR(Table1[[#This Row],[B1.Diff]]/Table1[[#This Row],[B1.Aud]],"ERR") -> -0.31555556 | X14: =_xlfn.IFNA(VLOOKUP(Table1[[#This Row],[MTP SKU Code]],'Audit Dimensions'!A:N,10,FALSE),"ARC") -> 0 | Y14: =IFERROR(Table1[[#This Row],[B2.Aud]]-Table1[[#This Row],[PW(gm)5]],"ERR") -> 0 | Z14: =IFERROR(Table1[[#This Row],[B2.Diff]]/Table1[[#This Row],[B2.Aud]],"NA") -> NA | AA14: =_xlfn.IFNA(VLOOKUP(Table1[[#This Row],[MTP SKU Code]],'Audit Dimensions'!A:N,14,FALSE),"ARC") -> 0 | AB14: =IFERROR(Table1[[#This Row],[B3.Aud]]-Table1[[#This Row],[PW(gm)9]],"ERR") -> 0 | AC14: =IFERROR(Table1[[#This Row],[B3.Diff]]/Table1[[#This Row],[BaLL.Aud]],"ERR") -> 0 | AD14: =_xlfn.IFNA(VLOOKUP(Table1[[#This Row],[MTP SKU Code]],'Audit Dimensions'!A:U,16,FALSE),"ARC") -> 11250 | AE14: =IFERROR(1-Table1[[#This Row],[Gms]]/Table1[[#This Row],[BaLL.Aud]],"ERR") -> -0.31555556
A15: SL-VE-P | B15: SB | C15: 50 | D15: 29 | E15: 8 | F15: 1890 | O15: =((IFERROR((C15*D15*E15),0)+IFERROR((G15*H15*I15),0)+IFERROR((K15*L15*M15),0))/1000000)*35.32 -> 0.409712 | P15: =Table1[[#This Row],[Column15]]*$P$2*1000 -> 2458.272 | Q15: =F15+J15+N15 -> 1890 | R15: =MAX(Q15,O15) -> 1890 | S15: =MAX(R15,P15) -> 2458.272 | T15: =VLOOKUP(A15,'[1]MTP SKUs - Master Data'!$A:$B,2,FALSE) -> DI | U15: =_xlfn.IFNA(VLOOKUP(Table1[[#This Row],[MTP SKU Code]],'Audit Dimensions'!A:N,6,FALSE),"ARC") -> 1500 | V15: =IFERROR(Table1[[#This Row],[B1.Aud]]-Table1[[#This Row],[PW(gm)]],"ERR") -> -390 | W15: =IFERROR(Table1[[#This Row],[B1.Diff]]/Table1[[#This Row],[B1.Aud]],"ERR") -> -0.26 | X15: =_xlfn.IFNA(VLOOKUP(Table1[[#This Row],[MTP SKU Code]],'Audit Dimensions'!A:N,10,FALSE),"ARC") -> 0 | Y15: =IFERROR(Table1[[#This Row],[B2.Aud]]-Table1[[#This Row],[PW(gm)5]],"ERR") -> 0 | Z15: =IFERROR(Table1[[#This Row],[B2.Diff]]/Table1[[#This Row],[B2.Aud]],"NA") -> NA | AA15: =_xlfn.IFNA(VLOOKUP(Table1[[#This Row],[MTP SKU Code]],'Audit Dimensions'!A:N,14,FALSE),"ARC") -> 0 | AB15: =IFERROR(Table1[[#This Row],[B3.Aud]]-Table1[[#This Row],[PW(gm)9]],"ERR") -> 0 | AC15: =IFERROR(Table1[[#This Row],[B3.Diff]]/Table1[[#This Row],[BaLL.Aud]],"ERR") -> 0 | AD15: =_xlfn.IFNA(VLOOKUP(Table1[[#This Row],[MTP SKU Code]],'Audit Dimensions'!A:U,16,FALSE),"ARC") -> 1500 | AE15: =IFERROR(1-Table1[[#This Row],[Gms]]/Table1[[#This Row],[BaLL.Aud]],"ERR") -> -0.26
A16: S-RY | B16: SB | C16: =_xlfn.XLOOKUP(Table1[[#This Row],[MTP SKU Code]],'Audit Dimensions'!A:A,'Audit Dimensions'!C:C,0) -> 65 | D16: =_xlfn.XLOOKUP(Table1[[#This Row],[MTP SKU Code]],'Audit Dimensions'!$A:$A,'Audit Dimensions'!D:D,0) -> 18 | E16: =_xlfn.XLOOKUP(Table1[[#This Row],[MTP SKU Code]],'Audit Dimensions'!$A:$A,'Audit Dimensions'!E:E,0) -> 9 | F16: =_xlfn.XLOOKUP(Table1[[#This Row],[MTP SKU Code]],'Audit Dimensions'!$A:$A,'Audit Dimensions'!F:F,0) -> 3850 | G16: =_xlfn.XLOOKUP(Table1[[#This Row],[MTP SKU Code]],'Audit Dimensions'!$A:$A,'Audit Dimensions'!G:G,0) -> 0 | H16: =_xlfn.XLOOKUP(Table1[[#This Row],[MTP SKU Code]],'Audit Dimensions'!$A:$A,'Audit Dimensions'!H:H,0) -> 0 | I16: =_xlfn.XLOOKUP(Table1[[#This Row],[MTP SKU Code]],'Audit Dimensions'!$A:$A,'Audit Dimensions'!I:I,0) -> 0 | J16: =_xlfn.XLOOKUP(Table1[[#This Row],[MTP SKU Code]],'Audit Dimensions'!$A:$A,'Audit Dimensions'!J:J,0) -> 0 | K16: =_xlfn.XLOOKUP(Table1[[#This Row],[MTP SKU Code]],'Audit Dimensions'!$A:$A,'Audit Dimensions'!K:K,0) -> 0 | L16: =_xlfn.XLOOKUP(Table1[[#This Row],[MTP SKU Code]],'Audit Dimensions'!$A:$A,'Audit Dimensions'!L:L,0) -> 0 | M16: =_xlfn.XLOOKUP(Table1[[#This Row],[MTP SKU Code]],'Audit Dimensions'!$A:$A,'Audit Dimensions'!M:M,0) -> 0 | N16: =_xlfn.XLOOKUP(Table1[[#This Row],[MTP SKU Code]],'Audit Dimensions'!$A:$A,'Audit Dimensions'!N:N,0) -> 0 | O16: =((IFERROR((C16*D16*E16),0)+IFERROR((G16*H16*I16),0)+IFERROR((K16*L16*M16),0))/1000000)*35.32 -> 0.3719196 | P16: =Table1[[#This Row],[Column15]]*$P$2*1000 -> 2231.5176 | Q16: =F16+J16+N16 -> 3850 | R16: =MAX(Q16,O16) -> 3850 | S16: =MAX(R16,P16) -> 3850 | T16: =VLOOKUP(A16,'[1]MTP SKUs - Master Data'!$A:$B,2,FALSE) -> Y | U16: =_xlfn.IFNA(VLOOKUP(Table1[[#This Row],[MTP SKU Code]],'Audit Dimensions'!A:N,6,FALSE),"ARC") -> 3850 | V16: =IFERROR(Table1[[#This Row],[B1.Aud]]-Table1[[#This Row],[PW(gm)]],"ERR") -> 0 | W16: =IFERROR(Table1[[#This Row],[B1.Diff]]/Table1[[#This Row],[B1.Aud]],"ERR") -> 0 | X16: =_xlfn.IFNA(VLOOKUP(Table1[[#This Row],[MTP SKU Code]],'Audit Dimensions'!A:N,10,FALSE),"ARC") -> 0 | Y16: =IFERROR(Table1[[#This Row],[B2.Aud]]-Table1[[#This Row],[PW(gm)5]],"ERR") -> 0 | Z16: =IFERROR(Table1[[#This Row],[B2.Diff]]/Table1[[#This Row],[B2.Aud]],"NA") -> NA | AA16: =_xlfn.IFNA(VLOOKUP(Table1[[#This Row],[MTP SKU Code]],'Audit Dimensions'!A:N,14,FALSE),"ARC") -> 0 | AB16: =IFERROR(Table1[[#This Row],[B3.Aud]]-Table1[[#This Row],[PW(gm)9]],"ERR") -> 0 | AC16: =IFERROR(Table1[[#This Row],[B3.Diff]]/Table1[[#This Row],[BaLL.Aud]],"ERR") -> 0 | AD16: =_xlfn.IFNA(VLOOKUP(Table1[[#This Row],[MTP SKU Code]],'Audit Dimensions'!A:U,16,FALSE),"ARC") -> 3850 | AE16: =IFERROR(1-Table1[[#This Row],[Gms]]/Table1[[#This Row],[BaLL.Aud]],"ERR") -> 0
A17: KH-EDL | B17: SB | C17: 34 | D17: 18 | E17: 3 | F17: =_xlfn.XLOOKUP(Table1[[#This Row],[MTP SKU Code]],'Audit Dimensions'!$A:$A,'Audit Dimensions'!F:F,0) -> 345 | G17: =_xlfn.XLOOKUP(Table1[[#This Row],[MTP SKU Code]],'Audit Dimensions'!$A:$A,'Audit Dimensions'!G:G,0) -> 0 | H17: =_xlfn.XLOOKUP(Table1[[#This Row],[MTP SKU Code]],'Audit Dimensions'!$A:$A,'Audit Dimensions'!H:H,0) -> 0 | I17: =_xlfn.XLOOKUP(Table1[[#This Row],[MTP SKU Code]],'Audit Dimensions'!$A:$A,'Audit Dimensions'!I:I,0) -> 0 | J17: =_xlfn.XLOOKUP(Table1[[#This Row],[MTP SKU Code]],'Audit Dimensions'!$A:$A,'Audit Dimensions'!J:J,0) -> 0 | K17: =_xlfn.XLOOKUP(Table1[[#This Row],[MTP SKU Code]],'Audit Dimensions'!$A:$A,'Audit Dimensions'!K:K,0) -> 0 | L17: =_xlfn.XLOOKUP(Table1[[#This Row],[MTP SKU Code]],'Audit Dimensions'!$A:$A,'Audit Dimensions'!L:L,0) -> 0 | M17: =_xlfn.XLOOKUP(Table1[[#This Row],[MTP SKU Code]],'Audit Dimensions'!$A:$A,'Audit Dimensions'!M:M,0) -> 0 | N17: =_xlfn.XLOOKUP(Table1[[#This Row],[MTP SKU Code]],'Audit Dimensions'!$A:$A,'Audit Dimensions'!N:N,0) -> 0 | O17: =((IFERROR((C17*D17*E17),0)+IFERROR((G17*H17*I17),0)+IFERROR((K17*L17*M17),0))/1000000)*35.32 -> 0.06484752 | P17: =Table1[[#This Row],[Column15]]*$P$2*1000 -> 389.08512 | Q17: =F17+J17+N17 -> 345 | R17: =MAX(Q17,O17) -> 345 | S17: =MAX(R17,P17) -> 389.08512 | T17: =VLOOKUP(A17,'[1]MTP SKUs - Master Data'!$A:$B,2,FALSE) -> RL | U17: =_xlfn.IFNA(VLOOKUP(Table1[[#This Row],[MTP SKU Code]],'Audit Dimensions'!A:N,6,FALSE),"ARC") -> 345 | V17: =IFERROR(Table1[[#This Row],[B1.Aud]]-Table1[[#This Row],[PW(gm)]],"ERR") -> 0 | W17: =IFERROR(Table1[[#This Row],[B1.Diff]]/Table1[[#This Row],[B1.Aud]],"ERR") -> 0 | X17: =_xlfn.IFNA(VLOOKUP(Table1[[#This Row],[MTP SKU Code]],'Audit Dimensions'!A:N,10,FALSE),"ARC") -> 0 | Y17: =IFERROR(Table1[[#This Row],[B2.Aud]]-Table1[[#This Row],[PW(gm)5]],"ERR") -> 0 | Z17: =IFERROR(Table1[[#This Row],[B2.Diff]]/Table1[[#This Row],[B2.Aud]],"NA") -> NA | AA17: =_xlfn.IFNA(VLOOKUP(Table1[[#This Row],[MTP SKU Code]],'Audit Dimensions'!A:N,14,FALSE),"ARC") -> 0 | AB17: =IFERROR(Table1[[#This Row],[B3.Aud]]-Table1[[#This Row],[PW(gm)9]],"ERR") -> 0 | AC17: =IFERROR(Table1[[#This Row],[B3.Diff]]/Table1[[#This Row],[BaLL.Aud]],"ERR") -> 0 | AD17: =_xlfn.IFNA(VLOOKUP(Table1[[#This Row],[MTP SKU Code]],'Audit Dimensions'!A:U,16,FALSE),"ARC") -> 345 | AE17: =IFERROR(1-Table1[[#This Row],[Gms]]/Table1[[#This Row],[BaLL.Aud]],"ERR") -> 0
A18: TU-MLE | B18: SB | C18: =_xlfn.XLOOKUP(Table1[[#This Row],[MTP SKU Code]],'Audit Dimensions'!A:A,'Audit Dimensions'!C:C,0) -> 126 | D18: =_xlfn.XLOOKUP(Table1[[#This Row],[MTP SKU Code]],'Audit Dimensions'!$A:$A,'Audit Dimensions'!D:D,0) -> 29 | E18: =_xlfn.XLOOKUP(Table1[[#This Row],[MTP SKU Code]],'Audit Dimensions'!$A:$A,'Audit Dimensions'!E:E,0) -> 6 | F18: 7870 | G18: =_xlfn.XLOOKUP(Table1[[#This Row],[MTP SKU Code]],'Audit Dimensions'!$A:$A,'Audit Dimensions'!G:G,0) -> 0 | H18: =_xlfn.XLOOKUP(Table1[[#This Row],[MTP SKU Code]],'Audit Dimensions'!$A:$A,'Audit Dimensions'!H:H,0) -> 0 | I18: =_xlfn.XLOOKUP(Table1[[#This Row],[MTP SKU Code]],'Audit Dimensions'!$A:$A,'Audit Dimensions'!I:I,0) -> 0 | J18: =_xlfn.XLOOKUP(Table1[[#This Row],[MTP SKU Code]],'Audit Dimensions'!$A:$A,'Audit Dimensions'!J:J,0) -> 0 | K18: =_xlfn.XLOOKUP(Table1[[#This Row],[MTP SKU Code]],'Audit Dimensions'!$A:$A,'Audit Dimensions'!K:K,0) -> 0 | L18: =_xlfn.XLOOKUP(Table1[[#This Row],[MTP SKU Code]],'Audit Dimensions'!$A:$A,'Audit Dimensions'!L:L,0) -> 0 | M18: =_xlfn.XLOOKUP(Table1[[#This Row],[MTP SKU Code]],'Audit Dimensions'!$A:$A,'Audit Dimensions'!M:M,0) -> 0 | N18: =_xlfn.XLOOKUP(Table1[[#This Row],[MTP SKU Code]],'Audit Dimensions'!$A:$A,'Audit Dimensions'!N:N,0) -> 0 | O18: =((IFERROR((C18*D18*E18),0)+IFERROR((G18*H18*I18),0)+IFERROR((K18*L18*M18),0))/1000000)*35.32 -> 0.77435568 | P18: =Table1[[#This Row],[Column15]]*$P$2*1000 -> 4646.1341 | Q18: =F18+J18+N18 -> 7870 | R18: =MAX(Q18,O18) -> 7870 | S18: =MAX(R18,P18) -> 7870 | T18: =VLOOKUP(A18,'[1]MTP SKUs - Master Data'!$A:$B,2,FALSE) -> Y | U18: =_xlfn.IFNA(VLOOKUP(Table1[[#This Row],[MTP SKU Code]],'Audit Dimensions'!A:N,6,FALSE),"ARC") -> 8100 | V18: =IFERROR(Table1[[#This Row],[B1.Aud]]-Table1[[#This Row],[PW(gm)]],"ERR") -> 230 | W18: =IFERROR(Table1[[#This Row],[B1.Diff]]/Table1[[#This Row],[B1.Aud]],"ERR") -> 0.028395062 | X18: =_xlfn.IFNA(VLOOKUP(Table1[[#This Row],[MTP SKU Code]],'Audit Dimensions'!A:N,10,FALSE),"ARC") -> 0 | Y18: =IFERROR(Table1[[#This Row],[B2.Aud]]-Table1[[#This Row],[PW(gm)5]],"ERR") -> 0 | Z18: =IFERROR(Table1[[#This Row],[B2.Diff]]/Table1[[#This Row],[B2.Aud]],"NA") -> NA | AA18: =_xlfn.IFNA(VLOOKUP(Table1[[#This Row],[MTP SKU Code]],'Audit Dimensions'!A:N,14,FALSE),"ARC") -> 0 | AB18: =IFERROR(Table1[[#This Row],[B3.Aud]]-Table1[[#This Row],[PW(gm)9]],"ERR") -> 0 | AC18: =IFERROR(Table1[[#This Row],[B3.Diff]]/Table1[[#This Row],[BaLL.Aud]],"ERR") -> 0 | AD18: =_xlfn.IFNA(VLOOKUP(Table1[[#This Row],[MTP SKU Code]],'Audit Dimensions'!A:U,16,FALSE),"ARC") -> 8100 | AE18: =IFERROR(1-Table1[[#This Row],[Gms]]/Table1[[#This Row],[BaLL.Aud]],"ERR") -> 0.028395062
A19: KH-SW-WB | B19: SB | C19: 28 | D19: =_xlfn.XLOOKUP(Table1[[#This Row],[MTP SKU Code]],'Audit Dimensions'!$A:$A,'Audit Dimensions'!D:D,0) -> 11 | E19: =_xlfn.XLOOKUP(Table1[[#This Row],[MTP SKU Code]],'Audit Dimensions'!$A:$A,'Audit Dimensions'!E:E,0) -> 6 | F19: 300 | G19: =_xlfn.XLOOKUP(Table1[[#This Row],[MTP SKU Code]],'Audit Dimensions'!$A:$A,'Audit Dimensions'!G:G,0) -> 0 | H19: =_xlfn.XLOOKUP(Table1[[#This Row],[MTP SKU Code]],'Audit Dimensions'!$A:$A,'Audit Dimensions'!H:H,0) -> 0 | I19: =_xlfn.XLOOKUP(Table1[[#This Row],[MTP SKU Code]],'Audit Dimensions'!$A:$A,'Audit Dimensions'!I:I,0) -> 0 | J19: =_xlfn.XLOOKUP(Table1[[#This Row],[MTP SKU Code]],'Audit Dimensions'!$A:$A,'Audit Dimensions'!J:J,0) -> 0 | K19: =_xlfn.XLOOKUP(Table1[[#This Row],[MTP SKU Code]],'Audit Dimensions'!$A:$A,'Audit Dimensions'!K:K,0) -> 0 | L19: =_xlfn.XLOOKUP(Table1[[#This Row],[MTP SKU Code]],'Audit Dimensions'!$A:$A,'Audit Dimensions'!L:L,0) -> 0 | M19: =_xlfn.XLOOKUP(Table1[[#This Row],[MTP SKU Code]],'Audit Dimensions'!$A:$A,'Audit Dimensions'!M:M,0) -> 0 | N19: =_xlfn.XLOOKUP(Table1[[#This Row],[MTP SKU Code]],'Audit Dimensions'!$A:$A,'Audit Dimensions'!N:N,0) -> 0 | O19: =((IFERROR((C19*D19*E19),0)+IFERROR((G19*H19*I19),0)+IFERROR((K19*L19*M19),0))/1000000)*35.32 -> 0.06527136 | P19: =Table1[[#This Row],[Column15]]*$P$2*1000 -> 391.62816 | Q19: =F19+J19+N19 -> 300 | R19: =MAX(Q19,O19) -> 300 | S19: =MAX(R19,P19) -> 391.62816 | T19: =VLOOKUP(A19,'[1]MTP SKUs - Master Data'!$A:$B,2,FALSE) -> Y | U19: =_xlfn.IFNA(VLOOKUP(Table1[[#This Row],[MTP SKU Code]],'Audit Dimensions'!A:N,6,FALSE),"ARC") -> 306 | V19: =IFERROR(Table1[[#This Row],[B1.Aud]]-Table1[[#This Row],[PW(gm)]],"ERR") -> 6 | W19: =IFERROR(Table1[[#This Row],[B1.Diff]]/Table1[[#This Row],[B1.Aud]],"ERR") -> 0.019607843 | X19: =_xlfn.IFNA(VLOOKUP(Table1[[#This Row],[MTP SKU Code]],'Audit Dimensions'!A:N,10,FALSE),"ARC") -> 0 | Y19: =IFERROR(Table1[[#This Row],[B2.Aud]]-Table1[[#This Row],[PW(gm)5]],"ERR") -> 0 | Z19: =IFERROR(Table1[[#This Row],[B2.Diff]]/Table1[[#This Row],[B2.Aud]],"NA") -> NA | AA19: =_xlfn.IFNA(VLOOKUP(Table1[[#This Row],[MTP SKU Code]],'Audit Dimensions'!A:N,14,FALSE),"ARC") -> 0 | AB19: =IFERROR(Table1[[#This Row],[B3.Aud]]-Table1[[#This Row],[PW(gm)9]],"ERR") -> 0 | AC19: =IFERROR(Table1[[#This Row],[B3.Diff]]/Table1[[#This Row],[BaLL.Aud]],"ERR") -> 0 | AD19: =_xlfn.IFNA(VLOOKUP(Table1[[#This Row],[MTP SKU Code]],'Audit Dimensions'!A:U,16,FALSE),"ARC") -> 306 | AE19: =IFERROR(1-Table1[[#This Row],[Gms]]/Table1[[#This Row],[BaLL.Aud]],"ERR") -> 0.019607843
A20: KH-SUT-10 | B20: SB | C20: 24 | D20: 24 | E20: 3 | F20: 385 | G20: =_xlfn.XLOOKUP(Table1[[#This Row],[MTP SKU Code]],'Audit Dimensions'!$A:$A,'Audit Dimensions'!G:G,0) -> 0 | H20: =_xlfn.XLOOKUP(Table1[[#This Row],[MTP SKU Code]],'Audit Dimensions'!$A:$A,'Audit Dimensions'!H:H,0) -> 0 | I20: =_xlfn.XLOOKUP(Table1[[#This Row],[MTP SKU Code]],'Audit Dimensions'!$A:$A,'Audit Dimensions'!I:I,0) -> 0 | J20: =_xlfn.XLOOKUP(Table1[[#This Row],[MTP SKU Code]],'Audit Dimensions'!$A:$A,'Audit Dimensions'!J:J,0) -> 0 | K20: =_xlfn.XLOOKUP(Table1[[#This Row],[MTP SKU Code]],'Audit Dimensions'!$A:$A,'Audit Dimensions'!K:K,0) -> 0 | L20: =_xlfn.XLOOKUP(Table1[[#This Row],[MTP SKU Code]],'Audit Dimensions'!$A:$A,'Audit Dimensions'!L:L,0) -> 0 | M20: =_xlfn.XLOOKUP(Table1[[#This Row],[MTP SKU Code]],'Audit Dimensions'!$A:$A,'Audit Dimensions'!M:M,0) -> 0 | N20: =_xlfn.XLOOKUP(Table1[[#This Row],[MTP SKU Code]],'Audit Dimensions'!$A:$A,'Audit Dimensions'!N:N,0) -> 0 | O20: =((IFERROR((C20*D20*E20),0)+IFERROR((G20*H20*I20),0)+IFERROR((K20*L20*M20),0))/1000000)*35.32 -> 0.06103296 | P20: =Table1[[#This Row],[Column15]]*$P$2*1000 -> 366.19776 | Q20: =F20+J20+N20 -> 385 | R20: =MAX(Q20,O20) -> 385 | S20: =MAX(R20,P20) -> 385 | T20: =VLOOKUP(A20,'[1]MTP SKUs - Master Data'!$A:$B,2,FALSE) -> Y | U20: =_xlfn.IFNA(VLOOKUP(Table1[[#This Row],[MTP SKU Code]],'Audit Dimensions'!A:N,6,FALSE),"ARC") -> 400 | V20: =IFERROR(Table1[[#This Row],[B1.Aud]]-Table1[[#This Row],[PW(gm)]],"ERR") -> 15 | W20: =IFERROR(Table1[[#This Row],[B1.Diff]]/Table1[[#This Row],[B1.Aud]],"ERR") -> 0.0375 | X20: =_xlfn.IFNA(VLOOKUP(Table1[[#This Row],[MTP SKU Code]],'Audit Dimensions'!A:N,10,FALSE),"ARC") -> 0 | Y20: =IFERROR(Table1[[#This Row],[B2.Aud]]-Table1[[#This Row],[PW(gm)5]],"ERR") -> 0 | Z20: =IFERROR(Table1[[#This Row],[B2.Diff]]/Table1[[#This Row],[B2.Aud]],"NA") -> NA | AA20: =_xlfn.IFNA(VLOOKUP(Table1[[#This Row],[MTP SKU Code]],'Audit Dimensions'!A:N,14,FALSE),"ARC") -> 0 | AB20: =IFERROR(Table1[[#This Row],[B3.Aud]]-Table1[[#This Row],[PW(gm)9]],"ERR") -> 0 | AC20: =IFERROR(Table1[[#This Row],[B3.Diff]]/Table1[[#This Row],[BaLL.Aud]],"ERR") -> 0 | AD20: =_xlfn.IFNA(VLOOKUP(Table1[[#This Row],[MTP SKU Code]],'Audit Dimensions'!A:U,16,FALSE),"ARC") -> 400 | AE20: =IFERROR(1-Table1[[#This Row],[Gms]]/Table1[[#This Row],[BaLL.Aud]],"ERR") -> 0.0375
A21: BT-NHE | B21: SB | C21: =_xlfn.XLOOKUP(Table1[[#This Row],[MTP SKU Code]],'Audit Dimensions'!A:A,'Audit Dimensions'!C:C,0) -> 57 | D21: =_xlfn.XLOOKUP(Table1[[#This Row],[MTP SKU Code]],'Audit Dimensions'!$A:$A,'Audit Dimensions'!D:D,0) -> 28 | E21: =_xlfn.XLOOKUP(Table1[[#This Row],[MTP SKU Code]],'Audit Dimensions'!$A:$A,'Audit Dimensions'!E:E,0) -> 9 | F21: 4800 | G21: =_xlfn.XLOOKUP(Table1[[#This Row],[MTP SKU Code]],'Audit Dimensions'!$A:$A,'Audit Dimensions'!G:G,0) -> 0 | H21: =_xlfn.XLOOKUP(Table1[[#This Row],[MTP SKU Code]],'Audit Dimensions'!$A:$A,'Audit Dimensions'!H:H,0) -> 0 | I21: =_xlfn.XLOOKUP(Table1[[#This Row],[MTP SKU Code]],'Audit Dimensions'!$A:$A,'Audit Dimensions'!I:I,0) -> 0 | J21: =_xlfn.XLOOKUP(Table1[[#This Row],[MTP SKU Code]],'Audit Dimensions'!$A:$A,'Audit Dimensions'!J:J,0) -> 0 | K21: =_xlfn.XLOOKUP(Table1[[#This Row],[MTP SKU Code]],'Audit Dimensions'!$A:$A,'Audit Dimensions'!K:K,0) -> 0 | L21: =_xlfn.XLOOKUP(Table1[[#This Row],[MTP SKU Code]],'Audit Dimensions'!$A:$A,'Audit Dimensions'!L:L,0) -> 0 | M21: =_xlfn.XLOOKUP(Table1[[#This Row],[MTP SKU Code]],'Audit Dimensions'!$A:$A,'Audit Dimensions'!M:M,0) -> 0 | N21: =_xlfn.XLOOKUP(Table1[[#This Row],[MTP SKU Code]],'Audit Dimensions'!$A:$A,'Audit Dimensions'!N:N,0) -> 0 | O21: =((IFERROR((C21*D21*E21),0)+IFERROR((G21*H21*I21),0)+IFERROR((K21*L21*M21),0))/1000000)*35.32 -> 0.50733648 | P21: =Table1[[#This Row],[Column15]]*$P$2*1000 -> 3044.0189 | Q21: =F21+J21+N21 -> 4800 | R21: =MAX(Q21,O21) -> 4800 | S21: =MAX(R21,P21) -> 4800 | T21: =VLOOKUP(A21,'[1]MTP SKUs - Master Data'!$A:$B,2,FALSE) -> Y | U21: =_xlfn.IFNA(VLOOKUP(Table1[[#This Row],[MTP SKU Code]],'Audit Dimensions'!A:N,6,FALSE),"ARC") -> 5010 | V21: =IFERROR(Table1[[#This Row],[B1.Aud]]-Table1[[#This Row],[PW(gm)]],"ERR") -> 210 | W21: =IFERROR(Table1[[#This Row],[B1.Diff]]/Table1[[#This Row],[B1.Aud]],"ERR") -> 0.041916168 | X21: =_xlfn.IFNA(VLOOKUP(Table1[[#This Row],[MTP SKU Code]],'Audit Dimensions'!A:N,10,FALSE),"ARC") -> 0 | Y21: =IFERROR(Table1[[#This Row],[B2.Aud]]-Table1[[#This Row],[PW(gm)5]],"ERR") -> 0 | Z21: =IFERROR(Table1[[#This Row],[B2.Diff]]/Table1[[#This Row],[B2.Aud]],"NA") -> NA | AA21: =_xlfn.IFNA(VLOOKUP(Table1[[#This Row],[MTP SKU Code]],'Audit Dimensions'!A:N,14,FALSE),"ARC") -> 0 | AB21: =IFERROR(Table1[[#This Row],[B3.Aud]]-Table1[[#This Row],[PW(gm)9]],"ERR") -> 0 | AC21: =IFERROR(Table1[[#This Row],[B3.Diff]]/Table1[[#This Row],[BaLL.Aud]],"ERR") -> 0 | AD21: =_xlfn.IFNA(VLOOKUP(Table1[[#This Row],[MTP SKU Code]],'Audit Dimensions'!A:U,16,FALSE),"ARC") -> 5010 | AE21: =IFERROR(1-Table1[[#This Row],[Gms]]/Table1[[#This Row],[BaLL.Aud]],"ERR") -> 0.041916168
A22: WA-PYS-S | B22: SB | C22: =_xlfn.XLOOKUP(Table1[[#This Row],[MTP SKU Code]],'Audit Dimensions'!A:A,'Audit Dimensions'!C:C,0) -> 70 | D22: 24 | E22: =_xlfn.XLOOKUP(Table1[[#This Row],[MTP SKU Code]],'Audit Dimensions'!$A:$A,'Audit Dimensions'!E:E,0) -> 5 | F22: 1850 | G22: =_xlfn.XLOOKUP(Table1[[#This Row],[MTP SKU Code]],'Audit Dimensions'!$A:$A,'Audit Dimensions'!G:G,0) -> 0 | H22: =_xlfn.XLOOKUP(Table1[[#This Row],[MTP SKU Code]],'Audit Dimensions'!$A:$A,'Audit Dimensions'!H:H,0) -> 0 | I22: =_xlfn.XLOOKUP(Table1[[#This Row],[MTP SKU Code]],'Audit Dimensions'!$A:$A,'Audit Dimensions'!I:I,0) -> 0 | J22: =_xlfn.XLOOKUP(Table1[[#This Row],[MTP SKU Code]],'Audit Dimensions'!$A:$A,'Audit Dimensions'!J:J,0) -> 0 | K22: =_xlfn.XLOOKUP(Table1[[#This Row],[MTP SKU Code]],'Audit Dimensions'!$A:$A,'Audit Dimensions'!K:K,0) -> 0 | L22: =_xlfn.XLOOKUP(Table1[[#This Row],[MTP SKU Code]],'Audit Dimensions'!$A:$A,'Audit Dimensions'!L:L,0) -> 0 | M22: =_xlfn.XLOOKUP(Table1[[#This Row],[MTP SKU Code]],'Audit Dimensions'!$A:$A,'Audit Dimensions'!M:M,0) -> 0 | N22: =_xlfn.XLOOKUP(Table1[[#This Row],[MTP SKU Code]],'Audit Dimensions'!$A:$A,'Audit Dimensions'!N:N,0) -> 0 | O22: =((IFERROR((C22*D22*E22),0)+IFERROR((G22*H22*I22),0)+IFERROR((K22*L22*M22),0))/1000000)*35.32 -> 0.296688 | P22: =Table1[[#This Row],[Column15]]*$P$2*1000 -> 1780.128 | Q22: =F22+J22+N22 -> 1850 | R22: =MAX(Q22,O22) -> 1850 | S22: =MAX(R22,P22) -> 1850 | T22: =VLOOKUP(A22,'[1]MTP SKUs - Master Data'!$A:$B,2,FALSE) -> Y | U22: =_xlfn.IFNA(VLOOKUP(Table1[[#This Row],[MTP SKU Code]],'Audit Dimensions'!A:N,6,FALSE),"ARC") -> 1940 | V22: =IFERROR(Table1[[#This Row],[B1.Aud]]-Table1[[#This Row],[PW(gm)]],"ERR") -> 90 | W22: =IFERROR(Table1[[#This Row],[B1.Diff]]/Table1[[#This Row],[B1.Aud]],"ERR") -> 0.046391753 | X22: =_xlfn.IFNA(VLOOKUP(Table1[[#This Row],[MTP SKU Code]],'Audit Dimensions'!A:N,10,FALSE),"ARC") -> 0 | Y22: =IFERROR(Table1[[#This Row],[B2.Aud]]-Table1[[#This Row],[PW(gm)5]],"ERR") -> 0 | Z22: =IFERROR(Table1[[#This Row],[B2.Diff]]/Table1[[#This Row],[B2.Aud]],"NA") -> NA | AA22: =_xlfn.IFNA(VLOOKUP(Table1[[#This Row],[MTP SKU Code]],'Audit Dimensions'!A:N,14,FALSE),"ARC") -> 0 | AB22: =IFERROR(Table1[[#This Row],[B3.Aud]]-Table1[[#This Row],[PW(gm)9]],"ERR") -> 0 | AC22: =IFERROR(Table1[[#This Row],[B3.Diff]]/Table1[[#This Row],[BaLL.Aud]],"ERR") -> 0 | AD22: =_xlfn.IFNA(VLOOKUP(Table1[[#This Row],[MTP SKU Code]],'Audit Dimensions'!A:U,16,FALSE),"ARC") -> 1940 | AE22: =IFERROR(1-Table1[[#This Row],[Gms]]/Table1[[#This Row],[BaLL.Aud]],"ERR") -> 0.046391753
A23: KH-TOC-18 | B23: SB | C23: =_xlfn.XLOOKUP(Table1[[#This Row],[MTP SKU Code]],'Audit Dimensions'!A:A,'Audit Dimensions'!C:C,0) -> 39 | D23: =_xlfn.XLOOKUP(Table1[[#This Row],[MTP SKU Code]],'Audit Dimensions'!$A:$A,'Audit Dimensions'!D:D,0) -> 30 | E23: =_xlfn.XLOOKUP(Table1[[#This Row],[MTP SKU Code]],'Audit Dimensions'!$A:$A,'Audit Dimensions'!E:E,0) -> 10 | F23: 2800 | G23: =_xlfn.XLOOKUP(Table1[[#This Row],[MTP SKU Code]],'Audit Dimensions'!$A:$A,'Audit Dimensions'!G:G,0) -> 0 | H23: =_xlfn.XLOOKUP(Table1[[#This Row],[MTP SKU Code]],'Audit Dimensions'!$A:$A,'Audit Dimensions'!H:H,0) -> 0 | I23: =_xlfn.XLOOKUP(Table1[[#This Row],[MTP SKU Code]],'Audit Dimensions'!$A:$A,'Audit Dimensions'!I:I,0) -> 0 | J23: =_xlfn.XLOOKUP(Table1[[#This Row],[MTP SKU Code]],'Audit Dimensions'!$A:$A,'Audit Dimensions'!J:J,0) -> 0 | K23: =_xlfn.XLOOKUP(Table1[[#This Row],[MTP SKU Code]],'Audit Dimensions'!$A:$A,'Audit Dimensions'!K:K,0) -> 0 | L23: =_xlfn.XLOOKUP(Table1[[#This Row],[MTP SKU Code]],'Audit Dimensions'!$A:$A,'Audit Dimensions'!L:L,0) -> 0 | M23: =_xlfn.XLOOKUP(Table1[[#This Row],[MTP SKU Code]],'Audit Dimensions'!$A:$A,'Audit Dimensions'!M:M,0) -> 0 | N23: =_xlfn.XLOOKUP(Table1[[#This Row],[MTP SKU Code]],'Audit Dimensions'!$A:$A,'Audit Dimensions'!N:N,0) -> 0 | O23: =((IFERROR((C23*D23*E23),0)+IFERROR((G23*H23*I23),0)+IFERROR((K23*L23*M23),0))/1000000)*35.32 -> 0.413244 | P23: =Table1[[#This Row],[Column15]]*$P$2*1000 -> 2479.464 | Q23: =F23+J23+N23 -> 2800 | R23: =MAX(Q23,O23) -> 2800 | S23: =MAX(R23,P23) -> 2800 | T23: =VLOOKUP(A23,'[1]MTP SKUs - Master Data'!$A:$B,2,FALSE) -> Y | U23: =_xlfn.IFNA(VLOOKUP(Table1[[#This Row],[MTP SKU Code]],'Audit Dimensions'!A:N,6,FALSE),"ARC") -> 2960 | V23: =IFERROR(Table1[[#This Row],[B1.Aud]]-Table1[[#This Row],[PW(gm)]],"ERR") -> 160 | W23: =IFERROR(Table1[[#This Row],[B1.Diff]]/Table1[[#This Row],[B1.Aud]],"ERR") -> 0.054054054 | X23: =_xlfn.IFNA(VLOOKUP(Table1[[#This Row],[MTP SKU Code]],'Audit Dimensions'!A:N,10,FALSE),"ARC") -> 0 | Y23: =IFERROR(Table1[[#This Row],[B2.Aud]]-Table1[[#This Row],[PW(gm)5]],"ERR") -> 0 | Z23: =IFERROR(Table1[[#This Row],[B2.Diff]]/Table1[[#This Row],[B2.Aud]],"NA") -> NA | AA23: =_xlfn.IFNA(VLOOKUP(Table1[[#This Row],[MTP SKU Code]],'Audit Dimensions'!A:N,14,FALSE),"ARC") -> 0 | AB23: =IFERROR(Table1[[#This Row],[B3.Aud]]-Table1[[#This Row],[PW(gm)9]],"ERR") -> 0 | AC23: =IFERROR(Table1[[#This Row],[B3.Diff]]/Table1[[#This Row],[BaLL.Aud]],"ERR") -> 0 | AD23: =_xlfn.IFNA(VLOOKUP(Table1[[#This Row],[MTP SKU Code]],'Audit Dimensions'!A:U,16,FALSE),"ARC") -> 2960 | AE23: =IFERROR(1-Table1[[#This Row],[Gms]]/Table1[[#This Row],[BaLL.Aud]],"ERR") -> 0.054054054
A24: SR-BKN-H | B24: SB | C24: =_xlfn.XLOOKUP(Table1[[#This Row],[MTP SKU Code]],'Audit Dimensions'!A:A,'Audit Dimensions'!C:C,0) -> 187 | D24: =_xlfn.XLOOKUP(Table1[[#This Row],[MTP SKU Code]],'Audit Dimensions'!$A:$A,'Audit Dimensions'!D:D,0) -> 43 | E24: =_xlfn.XLOOKUP(Table1[[#This Row],[MTP SKU Code]],'Audit Dimensions'!$A:$A,'Audit Dimensions'!E:E,0) -> 14 | F24: 55600 | G24: =_xlfn.XLOOKUP(Table1[[#This Row],[MTP SKU Code]],'Audit Dimensions'!$A:$A,'Audit Dimensions'!G:G,0) -> 0 | H24: =_xlfn.XLOOKUP(Table1[[#This Row],[MTP SKU Code]],'Audit Dimensions'!$A:$A,'Audit Dimensions'!H:H,0) -> 0 | I24: =_xlfn.XLOOKUP(Table1[[#This Row],[MTP SKU Code]],'Audit Dimensions'!$A:$A,'Audit Dimensions'!I:I,0) -> 0 | J24: =_xlfn.XLOOKUP(Table1[[#This Row],[MTP SKU Code]],'Audit Dimensions'!$A:$A,'Audit Dimensions'!J:J,0) -> 0 | K24: =_xlfn.XLOOKUP(Table1[[#This Row],[MTP SKU Code]],'Audit Dimensions'!$A:$A,'Audit Dimensions'!K:K,0) -> 0 | L24: =_xlfn.XLOOKUP(Table1[[#This Row],[MTP SKU Code]],'Audit Dimensions'!$A:$A,'Audit Dimensions'!L:L,0) -> 0 | M24: =_xlfn.XLOOKUP(Table1[[#This Row],[MTP SKU Code]],'Audit Dimensions'!$A:$A,'Audit Dimensions'!M:M,0) -> 0 | N24: =_xlfn.XLOOKUP(Table1[[#This Row],[MTP SKU Code]],'Audit Dimensions'!$A:$A,'Audit Dimensions'!N:N,0) -> 0 | O24: =((IFERROR((C24*D24*E24),0)+IFERROR((G24*H24*I24),0)+IFERROR((K24*L24*M24),0))/1000000)*35.32 -> 3.9761137 | P24: =Table1[[#This Row],[Column15]]*$P$2*1000 -> 23856.682 | Q24: =F24+J24+N24 -> 55600 | R24: =MAX(Q24,O24) -> 55600 | S24: =MAX(R24,P24) -> 55600 | T24: =VLOOKUP(A24,'[1]MTP SKUs - Master Data'!$A:$B,2,FALSE) -> Y | U24: =_xlfn.IFNA(VLOOKUP(Table1[[#This Row],[MTP SKU Code]],'Audit Dimensions'!A:N,6,FALSE),"ARC") -> 58920 | V24: =IFERROR(Table1[[#This Row],[B1.Aud]]-Table1[[#This Row],[PW(gm)]],"ERR") -> 3320 | W24: =IFERROR(Table1[[#This Row],[B1.Diff]]/Table1[[#This Row],[B1.Aud]],"ERR") -> 0.05634759 | X24: =_xlfn.IFNA(VLOOKUP(Table1[[#This Row],[MTP SKU Code]],'Audit Dimensions'!A:N,10,FALSE),"ARC") -> 0 | Y24: =IFERROR(Table1[[#This Row],[B2.Aud]]-Table1[[#This Row],[PW(gm)5]],"ERR") -> 0 | Z24: =IFERROR(Table1[[#This Row],[B2.Diff]]/Table1[[#This Row],[B2.Aud]],"NA") -> NA | AA24: =_xlfn.IFNA(VLOOKUP(Table1[[#This Row],[MTP SKU Code]],'Audit Dimensions'!A:N,14,FALSE),"ARC") -> 0 | AB24: =IFERROR(Table1[[#This Row],[B3.Aud]]-Table1[[#This Row],[PW(gm)9]],"ERR") -> 0 | AC24: =IFERROR(Table1[[#This Row],[B3.Diff]]/Table1[[#This Row],[BaLL.Aud]],"ERR") -> 0 | AD24: =_xlfn.IFNA(VLOOKUP(Table1[[#This Row],[MTP SKU Code]],'Audit Dimensions'!A:U,16,FALSE),"ARC") -> 58920 | AE24: =IFERROR(1-Table1[[#This Row],[Gms]]/Table1[[#This Row],[BaLL.Aud]],"ERR") -> 0.05634759
A25: ST-HES | B25: SB | C25: 85 | D25: 66 | E25: 5 | F25: 10750 | O25: =((IFERROR((C25*D25*E25),0)+IFERROR((G25*H25*I25),0)+IFERROR((K25*L25*M25),0))/1000000)*35.32 -> 0.990726 | P25: =Table1[[#This Row],[Column15]]*$P$2*1000 -> 5944.356 | Q25: =F25+J25+N25 -> 10750 | R25: =MAX(Q25,O25) -> 10750 | S25: =MAX(R25,P25) -> 10750 | T25: =VLOOKUP(A25,'[1]MTP SKUs - Master Data'!$A:$B,2,FALSE) -> DI | U25: =_xlfn.IFNA(VLOOKUP(Table1[[#This Row],[MTP SKU Code]],'Audit Dimensions'!A:N,6,FALSE),"ARC") -> 10100 | V25: =IFERROR(Table1[[#This Row],[B1.Aud]]-Table1[[#This Row],[PW(gm)]],"ERR") -> -650 | W25: =IFERROR(Table1[[#This Row],[B1.Diff]]/Table1[[#This Row],[B1.Aud]],"ERR") -> -0.064356436 | X25: =_xlfn.IFNA(VLOOKUP(Table1[[#This Row],[MTP SKU Code]],'Audit Dimensions'!A:N,10,FALSE),"ARC") -> 0 | Y25: =IFERROR(Table1[[#This Row],[B2.Aud]]-Table1[[#This Row],[PW(gm)5]],"ERR") -> 0 | Z25: =IFERROR(Table1[[#This Row],[B2.Diff]]/Table1[[#This Row],[B2.Aud]],"NA") -> NA | AA25: =_xlfn.IFNA(VLOOKUP(Table1[[#This Row],[MTP SKU Code]],'Audit Dimensions'!A:N,14,FALSE),"ARC") -> 0 | AB25: =IFERROR(Table1[[#This Row],[B3.Aud]]-Table1[[#This Row],[PW(gm)9]],"ERR") -> 0 | AC25: =IFERROR(Table1[[#This Row],[B3.Diff]]/Table1[[#This Row],[BaLL.Aud]],"ERR") -> 0 | AD25: =_xlfn.IFNA(VLOOKUP(Table1[[#This Row],[MTP SKU Code]],'Audit Dimensions'!A:U,16,FALSE),"ARC") -> 10100 | AE25: =IFERROR(1-Table1[[#This Row],[Gms]]/Table1[[#This Row],[BaLL.Aud]],"ERR") -> -0.064356436
A26: SB-NBK | B26: SB | C26: =_xlfn.XLOOKUP(Table1[[#This Row],[MTP SKU Code]],'Audit Dimensions'!A:A,'Audit Dimensions'!C:C,0) -> 159 | D26: =_xlfn.XLOOKUP(Table1[[#This Row],[MTP SKU Code]],'Audit Dimensions'!$A:$A,'Audit Dimensions'!D:D,0) -> 33 | E26: =_xlfn.XLOOKUP(Table1[[#This Row],[MTP SKU Code]],'Audit Dimensions'!$A:$A,'Audit Dimensions'!E:E,0) -> 9 | F26: 18800 | G26: =_xlfn.XLOOKUP(Table1[[#This Row],[MTP SKU Code]],'Audit Dimensions'!$A:$A,'Audit Dimensions'!G:G,0) -> 0 | H26: =_xlfn.XLOOKUP(Table1[[#This Row],[MTP SKU Code]],'Audit Dimensions'!$A:$A,'Audit Dimensions'!H:H,0) -> 0 | I26: =_xlfn.XLOOKUP(Table1[[#This Row],[MTP SKU Code]],'Audit Dimensions'!$A:$A,'Audit Dimensions'!I:I,0) -> 0 | J26: =_xlfn.XLOOKUP(Table1[[#This Row],[MTP SKU Code]],'Audit Dimensions'!$A:$A,'Audit Dimensions'!J:J,0) -> 0 | K26: =_xlfn.XLOOKUP(Table1[[#This Row],[MTP SKU Code]],'Audit Dimensions'!$A:$A,'Audit Dimensions'!K:K,0) -> 0 | L26: =_xlfn.XLOOKUP(Table1[[#This Row],[MTP SKU Code]],'Audit Dimensions'!$A:$A,'Audit Dimensions'!L:L,0) -> 0 | M26: =_xlfn.XLOOKUP(Table1[[#This Row],[MTP SKU Code]],'Audit Dimensions'!$A:$A,'Audit Dimensions'!M:M,0) -> 0 | N26: =_xlfn.XLOOKUP(Table1[[#This Row],[MTP SKU Code]],'Audit Dimensions'!$A:$A,'Audit Dimensions'!N:N,0) -> 0 | O26: =((IFERROR((C26*D26*E26),0)+IFERROR((G26*H26*I26),0)+IFERROR((K26*L26*M26),0))/1000000)*35.32 -> 1.6679164 | P26: =Table1[[#This Row],[Column15]]*$P$2*1000 -> 10007.498 | Q26: =F26+J26+N26 -> 18800 | R26: =MAX(Q26,O26) -> 18800 | S26: =MAX(R26,P26) -> 18800 | T26: =VLOOKUP(A26,'[1]MTP SKUs - Master Data'!$A:$B,2,FALSE) -> Y | U26: =_xlfn.IFNA(VLOOKUP(Table1[[#This Row],[MTP SKU Code]],'Audit Dimensions'!A:N,6,FALSE),"ARC") -> 20000 | V26: =IFERROR(Table1[[#This Row],[B1.Aud]]-Table1[[#This Row],[PW(gm)]],"ERR") -> 1200 | W26: =IFERROR(Table1[[#This Row],[B1.Diff]]/Table1[[#This Row],[B1.Aud]],"ERR") -> 0.06 | X26: =_xlfn.IFNA(VLOOKUP(Table1[[#This Row],[MTP SKU Code]],'Audit Dimensions'!A:N,10,FALSE),"ARC") -> 0 | Y26: =IFERROR(Table1[[#This Row],[B2.Aud]]-Table1[[#This Row],[PW(gm)5]],"ERR") -> 0 | Z26: =IFERROR(Table1[[#This Row],[B2.Diff]]/Table1[[#This Row],[B2.Aud]],"NA") -> NA | AA26: =_xlfn.IFNA(VLOOKUP(Table1[[#This Row],[MTP SKU Code]],'Audit Dimensions'!A:N,14,FALSE),"ARC") -> 0 | AB26: =IFERROR(Table1[[#This Row],[B3.Aud]]-Table1[[#This Row],[PW(gm)9]],"ERR") -> 0 | AC26: =IFERROR(Table1[[#This Row],[B3.Diff]]/Table1[[#This Row],[BaLL.Aud]],"ERR") -> 0 | AD26: =_xlfn.IFNA(VLOOKUP(Table1[[#This Row],[MTP SKU Code]],'Audit Dimensions'!A:U,16,FALSE),"ARC") -> 20000 | AE26: =IFERROR(1-Table1[[#This Row],[Gms]]/Table1[[#This Row],[BaLL.Aud]],"ERR") -> 0.06
A27: TS-NL-A | B27: SB | C27: =_xlfn.XLOOKUP(Table1[[#This Row],[MTP SKU Code]],'Audit Dimensions'!A:A,'Audit Dimensions'!C:C,0) -> 36 | D27: =_xlfn.XLOOKUP(Table1[[#This Row],[MTP SKU Code]],'Audit Dimensions'!$A:$A,'Audit Dimensions'!D:D,0) -> 25 | E27: =_xlfn.XLOOKUP(Table1[[#This Row],[MTP SKU Code]],'Audit Dimensions'!$A:$A,'Audit Dimensions'!E:E,0) -> 4 | F27: 1515 | O27: =((IFERROR((C27*D27*E27),0)+IFERROR((G27*H27*I27),0)+IFERROR((K27*L27*M27),0))/1000000)*35.32 -> 0.127152 | P27: =Table1[[#This Row],[Column15]]*$P$2*1000 -> 762.912 | Q27: =F27+J27+N27 -> 1515 | R27: =MAX(Q27,O27) -> 1515 | S27: =MAX(R27,P27) -> 1515 | T27: =VLOOKUP(A27,'[1]MTP SKUs - Master Data'!$A:$B,2,FALSE) -> DI | U27: =_xlfn.IFNA(VLOOKUP(Table1[[#This Row],[MTP SKU Code]],'Audit Dimensions'!A:N,6,FALSE),"ARC") -> 1430 | V27: =IFERROR(Table1[[#This Row],[B1.Aud]]-Table1[[#This Row],[PW(gm)]],"ERR") -> -85 | W27: =IFERROR(Table1[[#This Row],[B1.Diff]]/Table1[[#This Row],[B1.Aud]],"ERR") -> -0.059440559 | X27: =_xlfn.IFNA(VLOOKUP(Table1[[#This Row],[MTP SKU Code]],'Audit Dimensions'!A:N,10,FALSE),"ARC") -> 0 | Y27: =IFERROR(Table1[[#This Row],[B2.Aud]]-Table1[[#This Row],[PW(gm)5]],"ERR") -> 0 | Z27: =IFERROR(Table1[[#This Row],[B2.Diff]]/Table1[[#This Row],[B2.Aud]],"NA") -> NA | AA27: =_xlfn.IFNA(VLOOKUP(Table1[[#This Row],[MTP SKU Code]],'Audit Dimensions'!A:N,14,FALSE),"ARC") -> 0 | AB27: =IFERROR(Table1[[#This Row],[B3.Aud]]-Table1[[#This Row],[PW(gm)9]],"ERR") -> 0 | AC27: =IFERROR(Table1[[#This Row],[B3.Diff]]/Table1[[#This Row],[BaLL.Aud]],"ERR") -> 0 | AD27: =_xlfn.IFNA(VLOOKUP(Table1[[#This Row],[MTP SKU Code]],'Audit Dimensions'!A:U,16,FALSE),"ARC") -> 1430 | AE27: =IFERROR(1-Table1[[#This Row],[Gms]]/Table1[[#This Row],[BaLL.Aud]],"ERR") -> -0.059440559
